<?xml version="1.0"?>
<robot name="g1_29dof_mode_12">
  <material name="dark">
    <color rgba="0.2 0.2 0.2 1"/>
  </material>
  <material name="white">
    <color rgba="0.7 0.7 0.7 1"/>
  </material>
  <link name="pelvis">
    <inertial>
      <origin xyz="0 0 -0.07605" rpy="0 0 0"/>
      <mass value="3.813"/>
      <inertia ixx="0.010549" ixy="0" ixz="2.1E-06" iyy="0.0093089" iyz="0" izz="0.0079184"/>
    </inertial>
    <visual>
      <origin xyz="0 0 0" rpy="0 0 0"/>
      <geometry>
        <mesh filename="meshes/g1/pelvis.STL"/>
      </geometry>
      <material name="dark"/>
    </visual>
    <collision>
      <origin xyz="0 0 -0.08"/>
      <geometry>
        <sphere radius="0.07"/>
      </geometry>
    </collision>
  </link>
  <link name="pelvis_contour_link">
    <inertial>
      <origin xyz="0 0 0" rpy="0 0 0"/>
      <mass value="0.001"/>
      <inertia ixx="1e-7" ixy="0" ixz="0" iyy="1e-7" iyz="0" izz="1e-7"/>
    </inertial>
    <visual>
      <origin xyz="0 0 0" rpy="0 0 0"/>
      <geometry>
        <mesh filename="meshes/g1/pelvis_contour_link.STL"/>
      </geometry>
      <material name="white"/>
    </visual>
  </link>
  <joint name="pelvis_contour_joint" type="fixed">
    <parent link="pelvis"/>
    <child link="pelvis_contour_link"/>
  </joint>
  <!-- Legs -->
  <link name="left_hip_pitch_link">
    <inertial>
      <origin xyz="0.002741 0.047791 -0.02606" rpy="0 0 0"/>
      <mass value="1.35"/>
      <inertia ixx="0.001811" ixy="3.68E-05" ixz="-3.44E-05" iyy="0.0014193" iyz="0.000171" izz="0.0012812"/>
    </inertial>
    <visual>
      <origin xyz="0 0 0" rpy="0 0 0"/>
      <geometry>
        <mesh filename="meshes/g1/left_hip_pitch_link.STL"/>
      </geometry>
      <material name="dark"/>
    </visual>
  </link>
  <joint name="left_hip_pitch_joint" type="revolute">
    <origin xyz="0 0.064452 -0.1027" rpy="0 0 0"/>
    <parent link="pelvis"/>
    <child link="left_hip_pitch_link"/>
    <axis xyz="0 1 0"/>
    <limit lower="-2.5307" upper="2.8798" effort="139" velocity="20"/>
  </joint>
  <link name="left_hip_roll_link">
    <inertial>
      <origin xyz="0.029812 -0.001045 -0.087934" rpy="0 0 0"/>
      <mass value="1.52"/>
      <inertia ixx="0.0023773" ixy="-3.8E-06" ixz="-0.0003908" iyy="0.0024123" iyz="1.84E-05" izz="0.0016595"/>
    </inertial>
    <visual>
      <origin xyz="0 0 0" rpy="0 0 0"/>
      <geometry>
        <mesh filename="meshes/g1/left_hip_roll_link.STL"/>
      </geometry>
      <material name="white"/>
    </visual>
    <collision>
      <origin xyz="0.02 0 -0.1"/>
      <geometry>
        <cylinder radius="0.05" length="0.2"/>
      </geometry>
    </collision>
  </link>
  <joint name="left_hip_roll_joint" type="revolute">
    <origin xyz="0 0.052 -0.030465" rpy="0 -0.1749 0"/>
    <parent link="left_hip_pitch_link"/>
    <child link="left_hip_roll_link"/>
    <axis xyz="1 0 0"/>
    <limit lower="-0.5236" upper="2.9671" effort="139" velocity="20"/>
  </joint>
  <link name="left_hip_yaw_link">
    <inertial>
      <origin xyz="-0.057709 -0.010981 -0.15078" rpy="0 0 0"/>
      <mass value="1.702"/>
      <inertia ixx="0.0057774" ixy="-0.0005411" ixz="-0.0023948" iyy="0.0076124" iyz="-0.0007072" izz="0.003149"/>
    </inertial>
    <visual>
      <origin xyz="0 0 0" rpy="0 0 0"/>
      <geometry>
        <mesh filename="meshes/g1/left_hip_yaw_link.STL"/>
      </geometry>
      <material name="white"/>
    </visual>
  </link>
  <joint name="left_hip_yaw_joint" type="revolute">
    <origin xyz="0.025001 0 -0.12412" rpy="0 0 0"/>
    <parent link="left_hip_roll_link"/>
    <child link="left_hip_yaw_link"/>
    <axis xyz="0 0 1"/>
    <limit lower="-2.7576" upper="2.7576" effort="88" velocity="32"/>
  </joint>
  <link name="left_knee_link">
    <inertial>
      <origin xyz="0.005457 0.003964 -0.12074" rpy="0 0 0"/>
      <mass value="1.932"/>
      <inertia ixx="0.011329" ixy="4.82E-05" ixz="-4.49E-05" iyy="0.011277" iyz="-0.0007146" izz="0.0015168"/>
    </inertial>
    <visual>
      <origin xyz="0 0 0" rpy="0 0 0"/>
      <geometry>
        <mesh filename="meshes/g1/left_knee_link.STL"/>
      </geometry>
      <material name="white"/>
    </visual>
    <collision>
      <origin xyz="0.02 0 -0.1"/>
      <geometry>
        <cylinder radius="0.05" length="0.2"/>
      </geometry>
    </collision>
  </link>
  <joint name="left_knee_joint" type="revolute">
    <origin xyz="-0.078273 0.0021489 -0.17734" rpy="0 0.1749 0"/>
    <parent link="left_hip_yaw_link"/>
    <child link="left_knee_link"/>
    <axis xyz="0 1 0"/>
    <limit lower="-0.087267" upper="2.8798" effort="139" velocity="20"/>
  </joint>
  <link name="left_ankle_pitch_link">
    <inertial>
      <origin xyz="-0.007269 0 0.011137" rpy="0 0 0"/>
      <mass value="0.074"/>
      <inertia ixx="8.4E-06" ixy="0" ixz="-2.9E-06" iyy="1.89E-05" iyz="0" izz="1.26E-05"/>
    </inertial>
    <visual>
      <origin xyz="0 0 0" rpy="0 0 0"/>
      <geometry>
        <mesh filename="meshes/g1/left_ankle_pitch_link.STL"/>
      </geometry>
      <material name="white"/>
    </visual>
  </link>
  <joint name="left_ankle_pitch_joint" type="revolute">
    <origin xyz="0 -9.4445E-05 -0.30001" rpy="0 0 0"/>
    <parent link="left_knee_link"/>
    <child link="left_ankle_pitch_link"/>
    <axis xyz="0 1 0"/>
    <limit lower="-0.87267" upper="0.5236" effort="35" velocity="30"/>
  </joint>
  <link name="left_ankle_roll_link">
    <inertial>
      <origin xyz="0.026505 0 -0.016425" rpy="0 0 0"/>
      <mass value="0.608"/>
      <inertia ixx="0.0002231" ixy="2E-07" ixz="8.91E-05" iyy="0.0016161" iyz="-1E-07" izz="0.0016667"/>
    </inertial>
    <visual>
      <origin xyz="0 0 0" rpy="0 0 0"/>
      <geometry>
        <mesh filename="meshes/g1/left_ankle_roll_link.STL"/>
      </geometry>
      <material name="dark"/>
    </visual>
    <collision>
      <origin xyz="0.075 -0.026 -0.025" rpy="0 1.5708 0"/>
      <geometry>
        <cylinder radius="0.01" length="0.05"/>
      </geometry>
    </collision>
    <collision>
      <origin xyz="0.0395 -0.018 -0.025" rpy="0 -1.5708 0"/>
      <geometry>
        <cylinder radius="0.008" length="0.167"/>
      </geometry>
    </collision>
    <collision>
      <origin xyz="0.039 -0.01 -0.025" rpy="0 -1.5708 0"/>
      <geometry>
        <cylinder radius="0.01" length="0.182"/>
      </geometry>
    </collision>
    <collision>
      <origin xyz="0.039 0 -0.025" rpy="0 -1.5708 0"/>
      <geometry>
        <cylinder radius="0.01" length="0.186"/>
      </geometry>
    </collision>
    <collision>
      <origin xyz="0.039 0.01 -0.025" rpy="0 -1.5708 0"/>
      <geometry>
        <cylinder radius="0.01" length="0.182"/>
      </geometry>
    </collision>
    <collision>
      <origin xyz="0.0395 0.018 -0.025" rpy="0 -1.5708 0"/>
      <geometry>
        <cylinder radius="0.008" length="0.167"/>
      </geometry>
    </collision>
    <collision>
      <origin xyz="0.075 0.026 -0.025" rpy="0 1.5708 0"/>
      <geometry>
        <cylinder radius="0.01" length="0.05"/>
      </geometry>
    </collision>
  </link>
  <joint name="left_ankle_roll_joint" type="revolute">
    <origin xyz="0 0 -0.017558" rpy="0 0 0"/>
    <parent link="left_ankle_pitch_link"/>
    <child link="left_ankle_roll_link"/>
    <axis xyz="1 0 0"/>
    <limit lower="-0.2618" upper="0.2618" effort="35" velocity="30"/>
  </joint>
  <link name="right_hip_pitch_link">
    <inertial>
      <origin xyz="0.002741 -0.047791 -0.02606" rpy="0 0 0"/>
      <mass value="1.35"/>
      <inertia ixx="0.001811" ixy="-3.68E-05" ixz="-3.44E-05" iyy="0.0014193" iyz="-0.000171" izz="0.0012812"/>
    </inertial>
    <visual>
      <origin xyz="0 0 0" rpy="0 0 0"/>
      <geometry>
        <mesh filename="meshes/g1/right_hip_pitch_link.STL"/>
      </geometry>
      <material name="dark"/>
    </visual>
  </link>
  <joint name="right_hip_pitch_joint" type="revolute">
    <origin xyz="0 -0.064452 -0.1027" rpy="0 0 0"/>
    <parent link="pelvis"/>
    <child link="right_hip_pitch_link"/>
    <axis xyz="0 1 0"/>
    <limit lower="-2.5307" upper="2.8798" effort="139" velocity="20"/>
  </joint>
  <link name="right_hip_roll_link">
    <inertial>
      <origin xyz="0.029812 0.001045 -0.087934" rpy="0 0 0"/>
      <mass value="1.52"/>
      <inertia ixx="0.0023773" ixy="3.8E-06" ixz="-0.0003908" iyy="0.0024123" iyz="-1.84E-05" izz="0.0016595"/>
    </inertial>
    <visual>
      <origin xyz="0 0 0" rpy="0 0 0"/>
      <geometry>
        <mesh filename="meshes/g1/right_hip_roll_link.STL"/>
      </geometry>
      <material name="white"/>
    </visual>
    <collision>
      <origin xyz="0.02 0 -0.1"/>
      <geometry>
        <cylinder radius="0.05" length="0.2"/>
      </geometry>
    </collision>
  </link>
  <joint name="right_hip_roll_joint" type="revolute">
    <origin xyz="0 -0.052 -0.030465" rpy="0 -0.1749 0"/>
    <parent link="right_hip_pitch_link"/>
    <child link="right_hip_roll_link"/>
    <axis xyz="1 0 0"/>
    <limit lower="-2.9671" upper="0.5236" effort="139" velocity="20"/>
  </joint>
  <link name="right_hip_yaw_link">
    <inertial>
      <origin xyz="-0.057709 0.010981 -0.15078" rpy="0 0 0"/>
      <mass value="1.702"/>
      <inertia ixx="0.0057774" ixy="0.0005411" ixz="-0.0023948" iyy="0.0076124" iyz="0.0007072" izz="0.003149"/>
    </inertial>
    <visual>
      <origin xyz="0 0 0" rpy="0 0 0"/>
      <geometry>
        <mesh filename="meshes/g1/right_hip_yaw_link.STL"/>
      </geometry>
      <material name="white"/>
    </visual>
  </link>
  <joint name="right_hip_yaw_joint" type="revolute">
    <origin xyz="0.025001 0 -0.12412" rpy="0 0 0"/>
    <parent link="right_hip_roll_link"/>
    <child link="right_hip_yaw_link"/>
    <axis xyz="0 0 1"/>
    <limit lower="-2.7576" upper="2.7576" effort="88" velocity="32"/>
  </joint>
  <link name="right_knee_link">
    <inertial>
      <origin xyz="0.005457 -0.003964 -0.12074" rpy="0 0 0"/>
      <mass value="1.932"/>
      <inertia ixx="0.011329" ixy="-4.82E-05" ixz="4.49E-05" iyy="0.011277" iyz="0.0007146" izz="0.0015168"/>
    </inertial>
    <visual>
      <origin xyz="0 0 0" rpy="0 0 0"/>
      <geometry>
        <mesh filename="meshes/g1/right_knee_link.STL"/>
      </geometry>
      <material name="white"/>
    </visual>
    <collision>
      <origin xyz="0.02 0 -0.1"/>
      <geometry>
        <cylinder radius="0.05" length="0.2"/>
      </geometry>
    </collision>
  </link>
  <joint name="right_knee_joint" type="revolute">
    <origin xyz="-0.078273 -0.0021489 -0.17734" rpy="0 0.1749 0"/>
    <parent link="right_hip_yaw_link"/>
    <child link="right_knee_link"/>
    <axis xyz="0 1 0"/>
    <limit lower="-0.087267" upper="2.8798" effort="139" velocity="20"/>
  </joint>
  <link name="right_ankle_pitch_link">
    <inertial>
      <origin xyz="-0.007269 0 0.011137" rpy="0 0 0"/>
      <mass value="0.074"/>
      <inertia ixx="8.4E-06" ixy="0" ixz="-2.9E-06" iyy="1.89E-05" iyz="0" izz="1.26E-05"/>
    </inertial>
    <visual>
      <origin xyz="0 0 0" rpy="0 0 0"/>
      <geometry>
        <mesh filename="meshes/g1/right_ankle_pitch_link.STL"/>
      </geometry>
      <material name="white"/>
    </visual>
  </link>
  <joint name="right_ankle_pitch_joint" type="revolute">
    <origin xyz="0 9.4445E-05 -0.30001" rpy="0 0 0"/>
    <parent link="right_knee_link"/>
    <child link="right_ankle_pitch_link"/>
    <axis xyz="0 1 0"/>
    <limit lower="-0.87267" upper="0.5236" effort="35" velocity="30"/>
  </joint>
  <link name="right_ankle_roll_link">
    <inertial>
      <origin xyz="0.026505 0 -0.016425" rpy="0 0 0"/>
      <mass value="0.608"/>
      <inertia ixx="0.0002231" ixy="-2E-07" ixz="8.91E-05" iyy="0.0016161" iyz="1E-07" izz="0.0016667"/>
    </inertial>
    <visual>
      <origin xyz="0 0 0" rpy="0 0 0"/>
      <geometry>
        <mesh filename="meshes/g1/right_ankle_roll_link.STL"/>
      </geometry>
      <material name="dark"/>
    </visual>
    <collision>
      <origin xyz="0.075 -0.026 -0.025" rpy="0 1.5708 0"/>
      <geometry>
        <cylinder radius="0.01" length="0.05"/>
      </geometry>
    </collision>
    <collision>
      <origin xyz="0.0395 -0.018 -0.025" rpy="0 -1.5708 0"/>
      <geometry>
        <cylinder radius="0.008" length="0.167"/>
      </geometry>
    </collision>
    <collision>
      <origin xyz="0.039 -0.01 -0.025" rpy="0 -1.5708 0"/>
      <geometry>
        <cylinder radius="0.01" length="0.182"/>
      </geometry>
    </collision>
    <collision>
      <origin xyz="0.039 0 -0.025" rpy="0 -1.5708 0"/>
      <geometry>
        <cylinder radius="0.01" length="0.186"/>
      </geometry>
    </collision>
    <collision>
      <origin xyz="0.039 0.01 -0.025" rpy="0 -1.5708 0"/>
      <geometry>
        <cylinder radius="0.01" length="0.182"/>
      </geometry>
    </collision>
    <collision>
      <origin xyz="0.0395 0.018 -0.025" rpy="0 -1.5708 0"/>
      <geometry>
        <cylinder radius="0.008" length="0.167"/>
      </geometry>
    </collision>
    <collision>
      <origin xyz="0.075 0.026 -0.025" rpy="0 1.5708 0"/>
      <geometry>
        <cylinder radius="0.01" length="0.05"/>
      </geometry>
    </collision>
  </link>
  <joint name="right_ankle_roll_joint" type="revolute">
    <origin xyz="0 0 -0.017558" rpy="0 0 0"/>
    <parent link="right_ankle_pitch_link"/>
    <child link="right_ankle_roll_link"/>
    <axis xyz="1 0 0"/>
    <limit lower="-0.2618" upper="0.2618" effort="35" velocity="30"/>
  </joint>
  <!-- Torso -->
  <link name="waist_yaw_link">
    <inertial>
      <origin xyz="0.003494 0.000233 0.018034" rpy="0 0 0"/>
      <mass value="0.214"/>
      <inertia ixx="0.00010673" ixy="2.703E-06" ixz="-7.631E-06" iyy="0.00010422" iyz="-2.01E-07" izz="0.0001625"/>
    </inertial>
    <visual>
      <origin xyz="0 0 0" rpy="0 0 0"/>
      <geometry>
        <mesh filename="meshes/g1/waist_yaw_link_rev_1_0.STL"/>
      </geometry>
      <material name="white"/>
    </visual>
  </link>
  <joint name="waist_yaw_joint" type="revolute">
    <origin xyz="0 0 0" rpy="0 0 0"/>
    <parent link="pelvis"/>
    <child link="waist_yaw_link"/>
    <axis xyz="0 0 1"/>
    <limit lower="-2.618" upper="2.618" effort="88" velocity="32"/>
  </joint>
  <link name="waist_roll_link">
    <inertial>
      <origin xyz="0 2.3E-05 0" rpy="0 0 0"/>
      <mass value="0.086"/>
      <inertia ixx="7.079E-06" ixy="0" ixz="0" iyy="6.339E-06" iyz="0" izz="8.245E-06"/>
    </inertial>
    <visual>
      <origin xyz="0 0 0" rpy="0 0 0"/>
      <geometry>
        <mesh filename="meshes/g1/waist_roll_link_rev_1_0.STL"/>
      </geometry>
      <material name="white"/>
    </visual>
  </link>
  <joint name="waist_roll_joint" type="revolute">
    <origin xyz="-0.0039635 0 0.044" rpy="0 0 0"/>
    <parent link="waist_yaw_link"/>
    <child link="waist_roll_link"/>
    <axis xyz="1 0 0"/>
    <limit lower="-0.52" upper="0.52" effort="35" velocity="30"/>
  </joint>
  <link name="torso_link">
    <inertial>
      <origin xyz="0.000931 0.000346 0.15082" rpy="0 0 0"/>
      <mass value="6.78"/>
      <inertia ixx="0.05905" ixy="3.3302E-05" ixz="-0.0017715" iyy="0.047014" iyz="-2.2399E-05" izz="0.025652"/>
    </inertial>
    <visual>
      <origin xyz="0 0 0" rpy="0 0 0"/>
      <geometry>
        <mesh filename="meshes/g1/torso_link_rev_1_0.STL"/>
      </geometry>
      <material name="white"/>
    </visual>
    <collision>
      <origin xyz="0.005 0 0.22" rpy="1.5708 0 0"/>
      <geometry>
        <cylinder radius="0.073" length="0.064"/>
      </geometry>
    </collision>
    <collision>
      <origin xyz="0.005 0 0.13" rpy="1.5708 0 0"/>
      <geometry>
        <cylinder radius="0.07" length="0.056"/>
      </geometry>
    </collision>
    <collision>
      <origin xyz="0.005 0 0.06" rpy="1.5708 0 0"/>
      <geometry>
        <cylinder radius="0.065" length="0.04"/>
      </geometry>
    </collision>
    <collision>
      <origin xyz="0.01 0 0.415" rpy="3.1416 0 0"/>
      <geometry>
        <cylinder radius="0.068" length="0.01"/>
      </geometry>
    </collision>
  </link>
  <joint name="waist_pitch_joint" type="revolute">
    <origin xyz="0 0 0" rpy="0 0 0"/>
    <parent link="waist_roll_link"/>
    <child link="torso_link"/>
    <axis xyz="0 1 0"/>
    <limit lower="-0.52" upper="0.52" effort="35" velocity="30"/>
  </joint>
  <!-- LOGO -->
  <joint name="logo_joint" type="fixed">
    <origin xyz="0.0039635 0 -0.044" rpy="0 0 0"/>
    <parent link="torso_link"/>
    <child link="logo_link"/>
  </joint>
  <link name="logo_link">
    <inertial>
      <origin xyz="0 0 0" rpy="0 0 0"/>
      <mass value="0.001"/>
      <inertia ixx="1e-7" ixy="0" ixz="0" iyy="1e-7" iyz="0" izz="1e-7"/>
    </inertial>
    <visual>
      <origin xyz="0 0 0" rpy="0 0 0"/>
      <geometry>
        <mesh filename="meshes/g1/logo_link.STL"/>
      </geometry>
      <material name="dark"/>
    </visual>
  </link>
  <!-- Head -->
  <link name="head_link">
    <inertial>
      <origin xyz="0.005267 0.000299 0.449869" rpy="0 0 0"/>
      <mass value="1.036"/>
      <inertia ixx="0.004085051" ixy="-2.543E-06" ixz="-6.9455E-05" iyy="0.004185212" iyz="-3.726E-06" izz="0.001807911"/>
    </inertial>
    <visual>
      <origin xyz="0 0 0" rpy="0 0 0"/>
      <geometry>
        <mesh filename="meshes/g1/head_link.STL"/>
      </geometry>
      <material name="dark"/>
    </visual>
  </link>
  <joint name="head_joint" type="fixed">
    <origin xyz="0.0039635 0 -0.044" rpy="0 0 0"/>
    <parent link="torso_link"/>
    <child link="head_link"/>
  </joint>
  <!-- IMU -->
  <link name="imu_in_torso"/>
  <joint name="imu_in_torso_joint" type="fixed">
    <origin xyz="-0.03959 -0.00224 0.14792" rpy="0 0 0"/>
    <parent link="torso_link"/>
    <child link="imu_in_torso"/>
  </joint>
  <link name="imu_in_pelvis"/>
  <joint name="imu_in_pelvis_joint" type="fixed">
    <origin xyz="0.04525 0 -0.08339" rpy="0 0 0"/>
    <parent link="pelvis"/>
    <child link="imu_in_pelvis"/>
  </joint>
  <!-- d435 -->
  <link name="d435_link"/>
  <joint name="d435_joint" type="fixed">
    <origin xyz="0.0576235 0.01753 0.42987" rpy="0 0.8307767239493009 0"/>
    <parent link="torso_link"/>
    <child link="d435_link"/>
  </joint>
  <!-- mid360 -->
  <link name="mid360_link"/>
  <joint name="mid360_joint" type="fixed">
    <origin xyz="0.0002835 0.00003 0.41618" rpy="0 0.04014257279586953 0"/>
    <parent link="torso_link"/>
    <child link="mid360_link"/>
  </joint>
  <!-- Arm -->
  <link name="left_shoulder_pitch_link">
    <inertial>
      <origin xyz="0 0.035892 -0.011628" rpy="0 0 0"/>
      <mass value="0.718"/>
      <inertia ixx="0.0004291" ixy="-9.2E-06" ixz="6.4E-06" iyy="0.000453" iyz="2.26E-05" izz="0.000423"/>
    </inertial>
    <visual>
      <origin xyz="0 0 0" rpy="0 0 0"/>
      <geometry>
        <mesh filename="meshes/g1/left_shoulder_pitch_link.STL"/>
      </geometry>
      <material name="white"/>
    </visual>
  </link>
  <joint name="left_shoulder_pitch_joint" type="revolute">
    <origin xyz="0.0039563 0.10022 0.24778" rpy="0.27931 5.4949E-05 -0.00019159"/>
    <parent link="torso_link"/>
    <child link="left_shoulder_pitch_link"/>
    <axis xyz="0 1 0"/>
    <limit lower="-3.0892" upper="2.6704" effort="25" velocity="37"/>
  </joint>
  <link name="left_shoulder_roll_link">
    <inertial>
      <origin xyz="-0.000227 0.00727 -0.063243" rpy="0 0 0"/>
      <mass value="0.643"/>
      <inertia ixx="0.0006177" ixy="-1E-06" ixz="8.7E-06" iyy="0.0006912" iyz="-5.3E-06" izz="0.0003894"/>
    </inertial>
    <visual>
      <origin xyz="0 0 0" rpy="0 0 0"/>
      <geometry>
        <mesh filename="meshes/g1/left_shoulder_roll_link.STL"/>
      </geometry>
      <material name="white"/>
    </visual>
  </link>
  <joint name="left_shoulder_roll_joint" type="revolute">
    <origin xyz="0 0.038 -0.013831" rpy="-0.27925 0 0"/>
    <parent link="left_shoulder_pitch_link"/>
    <child link="left_shoulder_roll_link"/>
    <axis xyz="1 0 0"/>
    <limit lower="-1.5882" upper="2.2515" effort="25" velocity="37"/>
  </joint>
  <link name="left_shoulder_yaw_link">
    <inertial>
      <origin xyz="0.010773 -0.002949 -0.072009" rpy="0 0 0"/>
      <mass value="0.734"/>
      <inertia ixx="0.0009988" ixy="7.9E-06" ixz="0.0001412" iyy="0.0010605" iyz="-2.86E-05" izz="0.0004354"/>
    </inertial>
    <visual>
      <origin xyz="0 0 0" rpy="0 0 0"/>
      <geometry>
        <mesh filename="meshes/g1/left_shoulder_yaw_link.STL"/>
      </geometry>
      <material name="white"/>
    </visual>
    <collision>
      <origin xyz="0 0 -0.015" rpy="3.1416 0 0"/>
      <geometry>
        <cylinder radius="0.035" length="0.13"/>
      </geometry>
    </collision>
  </link>
  <joint name="left_shoulder_yaw_joint" type="revolute">
    <origin xyz="0 0.00624 -0.1032" rpy="0 0 0"/>
    <parent link="left_shoulder_roll_link"/>
    <child link="left_shoulder_yaw_link"/>
    <axis xyz="0 0 1"/>
    <limit lower="-2.618" upper="2.618" effort="25" velocity="37"/>
  </joint>
  <link name="left_elbow_link">
    <inertial>
      <origin xyz="0.064956 0.004454 -0.010062" rpy="0 0 0"/>
      <mass value="0.6"/>
      <inertia ixx="0.0002891" ixy="6.53E-05" ixz="1.72E-05" iyy="0.0004152" iyz="-5.6E-06" izz="0.0004197"/>
    </inertial>
    <visual>
      <origin xyz="0 0 0" rpy="0 0 0"/>
      <geometry>
        <mesh filename="meshes/g1/left_elbow_link.STL"/>
      </geometry>
      <material name="white"/>
    </visual>
    <collision>
      <origin xyz="0.055 0 -0.01" rpy="0 -1.5708 0"/>
      <geometry>
        <cylinder radius="0.035" length="0.13"/>
      </geometry>
    </collision>
  </link>
  <joint name="left_elbow_joint" type="revolute">
    <origin xyz="0.015783 0 -0.080518" rpy="0 0 0"/>
    <parent link="left_shoulder_yaw_link"/>
    <child link="left_elbow_link"/>
    <axis xyz="0 1 0"/>
    <limit lower="-1.0472" upper="2.0944" effort="25" velocity="37"/>
  </joint>
  <joint name="left_wrist_roll_joint" type="revolute">
    <origin xyz="0.100 0.00188791 -0.010" rpy="0 0 0"/>
    <axis xyz="1 0 0"/>
    <parent link="left_elbow_link"/>
    <child link="left_wrist_roll_link"/>
    <limit effort="25" velocity="37" lower="-1.972222054" upper="1.972222054"/>
  </joint>
  <link name="left_wrist_roll_link">
    <inertial>
      <origin xyz="0.01713944778 0.00053759094 0.00000048864" rpy="0 0 0"/>
      <mass value="0.08544498"/>
      <inertia ixx="0.00004821544023" ixy="-0.00000424511021" ixz="0.00000000510599" iyy="0.00003722899093" iyz="-0.00000000123525" izz="0.00005482106541"/>
    </inertial>
    <visual>
      <origin xyz="0 0 0" rpy="0 0 0"/>
      <geometry>
        <mesh filename="meshes/g1/left_wrist_roll_link.STL"/>
      </geometry>
      <material name="white"/>
    </visual>
  </link>
  <joint name="left_wrist_pitch_joint" type="revolute">
    <origin xyz="0.038 0 0" rpy="0 0 0"/>
    <axis xyz="0 1 0"/>
    <parent link="left_wrist_roll_link"/>
    <child link="left_wrist_pitch_link"/>
    <limit effort="5" velocity="22" lower="-1.614429558" upper="1.614429558"/>
  </joint>
  <link name="left_wrist_pitch_link">
    <inertial>
      <origin xyz="0.02299989837 -0.00111685314 -0.00111658096" rpy="0 0 0"/>
      <mass value="0.48404956"/>
      <inertia ixx="0.00016579646273" ixy="-0.00001231206746" ixz="0.00001231699194" iyy="0.00042954057410" iyz="0.00000081417712" izz="0.00042953697654"/>
    </inertial>
    <visual>
      <origin xyz="0 0 0" rpy="0 0 0"/>
      <geometry>
        <mesh filename="meshes/g1/left_wrist_pitch_link.STL"/>
      </geometry>
      <material name="white"/>
    </visual>
  </link>
  <joint name="left_wrist_yaw_joint" type="revolute">
    <origin xyz="0.046 0 0" rpy="0 0 0"/>
    <axis xyz="0 0 1"/>
    <parent link="left_wrist_pitch_link"/>
    <child link="left_wrist_yaw_link"/>
    <limit effort="5" velocity="22" lower="-1.614429558" upper="1.614429558"/>
  </joint>
  <link name="left_wrist_yaw_link">
    <inertial>
      <origin xyz="0.02200381568 0.00049485096 0.00053861123" rpy="0 0 0"/>
      <mass value="0.08457647"/>
      <inertia ixx="0.00004929128828" ixy="-0.00000045735494" ixz="0.00000445867591" iyy="0.00005973338134" iyz="0.00000043217198" izz="0.00003928083826"/>
    </inertial>
    <visual>
      <origin xyz="0 0 0" rpy="0 0 0"/>
      <geometry>
        <mesh filename="meshes/g1/left_wrist_yaw_link.STL"/>
      </geometry>
      <material name="white"/>
    </visual>
    <!-- <collision>
      <origin xyz="0.075 0 0" rpy="0 -1.5708 0"/>
      <geometry>
        <cylinder radius="0.05" length="0.05"/>
      </geometry>
    </collision> -->
  </link>
  <joint name="left_hand_palm_joint" type="fixed">
    <origin xyz="0.0415 0.003 0" rpy="1.5708 3.1416 1.5708"/>
    <parent link="left_wrist_yaw_link"/>
    <child link="left_palm_link"/>
  </joint>
  <link
    name="left_palm_link">
    <inertial><origin xyz="-0.0029787944008666 -0.000452551657325986 0.036654705440297" rpy="0 0 0"/><mass value="0.16914"/><inertia ixx="0.00014" ixy="2.54e-06" ixz="6.91e-06" iyy="9.47e-05" iyz="-6.63e-06" izz="6e-05"/></inertial>
    <visual>
      <origin
        xyz="0 0 0"
        rpy="0 0 0" />
      <geometry>
        <mesh
          filename="meshes/left/left_palm_link.STL" />
      </geometry>
      <material
        name="">
        <color
          rgba="0.627450980392157 0.627450980392157 0.627450980392157 1" />
      </material>
    </visual>
    <collision>
      <origin
        xyz="0 0 0"
        rpy="0 0 0" />
      <geometry>
        <mesh
          filename="meshes/left/left_palm_link.STL" />
      </geometry>
    </collision>
  </link>
  <link
    name="left_finger1_link1">
    <inertial><origin xyz="-0.00312584337053766 0.00124334711478157 -0.00755622685821667" rpy="0 0 0"/><mass value="0.0075"/><inertia ixx="3.2e-07" ixy="-2e-08" ixz="0.0" iyy="3e-07" iyz="4e-08" izz="2.3e-07"/></inertial>
    <visual>
      <origin
        xyz="0 0 0"
        rpy="0 0 0" />
      <geometry>
        <mesh
          filename="meshes/left/left_finger1_link1.STL" />
      </geometry>
      <material
        name="">
        <color
          rgba="0.627450980392157 0.627450980392157 0.627450980392157 1" />
      </material>
    </visual>
    <!-- <collision>
      <origin
        xyz="0 0 0"
        rpy="0 0 0" />
      <geometry>
        <mesh
          filename="meshes/left/left_finger1_link1.STL" />
      </geometry>
    </collision> -->
  </link>
  <joint
    name="left_finger1_joint1"
    type="fixed">
    <origin
      xyz="0.00843985365597852 -0.0205866432293554 0.0288928344107784"
      rpy="1.5023139401368 0.43577167910554 3.11264835810693" />
    <parent
      link="left_palm_link" />
    <child
      link="left_finger1_link1" />
    <axis
      xyz="0 1 0" />
    <limit
      lower="0.0475"
      upper="1.6033"
      effort="0.4452"
      velocity="8.587" />
  </joint>
  <link
    name="left_finger1_link2">
    <inertial><origin xyz="-0.00142783471547994 1.46615421709184e-05 -0.0156342507741224" rpy="0 0 0"/><mass value="0.0248"/><inertia ixx="2.76e-06" ixy="2e-08" ixz="1e-08" iyy="2.81e-06" iyz="2e-08" izz="6.8e-07"/></inertial>
    <visual>
      <origin
        xyz="0 0 0"
        rpy="0 0 0" />
      <geometry>
        <mesh
          filename="meshes/left/left_finger1_link2.STL" />
      </geometry>
      <material
        name="">
        <color
          rgba="0.627450980392157 0.627450980392157 0.627450980392157 1" />
      </material>
    </visual>
    <collision>
      <origin
        xyz="0 0 0"
        rpy="0 0 0" />
      <geometry>
        <mesh
          filename="meshes/left/left_finger1_link2.STL" />
      </geometry>
    </collision>
  </link>
  <joint
    name="left_finger1_joint2"
    type="fixed">
    <origin
      xyz="-0.0054483 0.0058191 -0.01388"
      rpy="0.14937 -0.34623 1.5901" />
    <parent
      link="left_finger1_link1" />
    <child
      link="left_finger1_link2" />
    <axis
      xyz="0 -1 0" />
    <limit
      lower="-0.1387"
      upper="0.9324"
      effort="0.4259"
      velocity="11.1" />
  </joint>
  <link
    name="left_finger1_link3">
    <inertial><origin xyz="0.00112319665690949 1.57299540108416e-05 -0.0130565799894585" rpy="0 0 0"/><mass value="0.0165"/><inertia ixx="1.46e-06" ixy="0.0" ixz="-2e-08" iyy="1.42e-06" iyz="0.0" izz="4.5e-07"/></inertial>
    <visual>
      <origin
        xyz="0 0 0"
        rpy="0 0 0" />
      <geometry>
        <mesh
          filename="meshes/left/left_finger1_link3.STL" />
      </geometry>
      <material
        name="">
        <color
          rgba="0.627450980392157 0.627450980392157 0.627450980392157 1" />
      </material>
    </visual>
    <collision>
      <origin
        xyz="0 0 0"
        rpy="0 0 0" />
      <geometry>
        <mesh
          filename="meshes/left/left_finger1_link3.STL" />
      </geometry>
    </collision>
  </link>
  <joint
    name="left_finger1_joint3"
    type="fixed">
    <origin
      xyz="-0.000846961087777298 0.000991504133990267 -0.0346562987377679"
      rpy="0.0332538563601251 0.0117623260174173 -1.90877003040037" />
    <parent
      link="left_finger1_link2" />
    <child
      link="left_finger1_link3" />
    <axis
      xyz="0 1 0" />
    <limit
      lower="-0.4642"
      upper="1.5623"
      effort="0.1888"
      velocity="13.578" />
  </joint>
  <link
    name="left_finger1_link4">
    <inertial><origin xyz="0.00119215114836296 1.41428709807684e-05 -0.00821130287749315" rpy="0 0 0"/><mass value="0.0165"/><inertia ixx="1.18e-06" ixy="0.0" ixz="1.2e-07" iyy="1.25e-06" iyz="0.0" izz="5.1e-07"/></inertial>
    <visual>
      <origin
        xyz="0 0 0"
        rpy="0 0 0" />
      <geometry>
        <mesh
          filename="meshes/left/left_finger1_link4.STL" />
      </geometry>
      <material
        name="">
        <color
          rgba="0.529411764705882 0.549019607843137 0.549019607843137 1" />
      </material>
    </visual>
    <collision>
      <origin
        xyz="0 0 0"
        rpy="0 0 0" />
      <geometry>
        <mesh
          filename="meshes/left/left_finger1_link4.STL" />
      </geometry>
    </collision>
  </link>
  <joint
    name="left_finger1_joint4"
    type="fixed">
    <origin
      xyz="0 0 -0.0294999998969489"
      rpy="0 0 0" />
    <parent
      link="left_finger1_link3" />
    <child
      link="left_finger1_link4" />
    <axis
      xyz="0 1 0" />
    <limit
      lower="-0.4699"
      upper="1.5568"
      effort="0.1468"
      velocity="12.863" />
  </joint>
  <link
    name="left_finger1_tip_link">
    <inertial><origin xyz="-0.000321120906836544 5.07425935932157e-05 0.000622110779642859" rpy="0 0 0"/><mass value="0.0041"/><inertia ixx="5.5e-07" ixy="0.0" ixz="2e-08" iyy="5.2e-07" iyz="0.0" izz="2.7e-07"/></inertial>
    <visual>
      <origin
        xyz="0 0 0"
        rpy="0 0 0" />
      <geometry>
        <mesh
          filename="meshes/left/left_finger1_tip_link.STL" />
      </geometry>
      <material
        name="">
        <color
          rgba="0.529411764705882 0.549019607843137 0.549019607843137 1" />
      </material>
    </visual>
    <collision>
      <origin
        xyz="0 0 0"
        rpy="0 0 0" />
      <geometry>
        <mesh
          filename="meshes/left/left_finger1_tip_link.STL" />
      </geometry>
    </collision>
  </link>
  <joint
    name="left_finger1_tip_fixed"
    type="fixed">
    <origin
      xyz="0.00104999999999626 0 -0.0235000000000007"
      rpy="3.14159265358971 0 -3.14159265358979" />
    <parent
      link="left_finger1_link4" />
    <child
      link="left_finger1_tip_link" />
    <axis
      xyz="0 0 0" />
  </joint>
  <link
    name="left_finger2_link1">
    <inertial><origin xyz="-0.00134243892861889 -5.65576364214282e-09 0.000258175161295587" rpy="0 0 0"/><mass value="0.0032"/><inertia ixx="8e-08" ixy="0.0" ixz="-3e-08" iyy="7e-08" iyz="0.0" izz="8e-08"/></inertial>
    <visual>
      <origin
        xyz="0 0 0"
        rpy="0 0 0" />
      <geometry>
        <mesh
          filename="meshes/left/left_finger2_link1.STL" />
      </geometry>
      <material
        name="">
        <color
          rgba="0.627450980392157 0.627450980392157 0.627450980392157 1" />
      </material>
    </visual>
    <!-- <collision>
      <origin
        xyz="0 0 0"
        rpy="0 0 0" />
      <geometry>
        <mesh
          filename="meshes/left/left_finger2_link1.STL" />
      </geometry>
    </collision> -->
  </link>
  <joint
    name="left_finger2_joint1"
    type="fixed">
    <origin
      xyz="-0.00587008921400943 -0.0294338632807759 0.0919165306703557"
      rpy="0.110463316505378 -0.0251937198594477 0.223332069867641" />
    <parent
      link="left_palm_link" />
    <child
      link="left_finger2_link1" />
    <axis
      xyz="0 1 0" />
    <limit
      lower="-0.1585"
      upper="1.5604"
      effort="0.6188"
      velocity="8.203" />
  </joint>
  <link
    name="left_finger2_link2">
    <inertial><origin xyz="-0.00453252206258244 4.38298002711224e-07 0.0209110403187525" rpy="0 0 0"/><mass value="0.033"/><inertia ixx="6.31e-06" ixy="0.0" ixz="-1.6e-07" iyy="6.34e-06" iyz="0.0" izz="8.9e-07"/></inertial>
    <visual>
      <origin
        xyz="0 0 0"
        rpy="0 0 0" />
      <geometry>
        <mesh
          filename="meshes/left/left_finger2_link2.STL" />
      </geometry>
      <material
        name="">
        <color
          rgba="0.627450980392157 0.627450980392157 0.627450980392157 1" />
      </material>
    </visual>
    <collision>
      <origin
        xyz="0 0 0"
        rpy="0 0 0" />
      <geometry>
        <mesh
          filename="meshes/left/left_finger2_link2.STL" />
      </geometry>
    </collision>
  </link>
  <joint
    name="left_finger2_joint2"
    type="fixed">
    <origin
      xyz="0.000389540189408399 0 0.00402230398376657"
      rpy="0 -0.0462278050739338 0" />
    <parent
      link="left_finger2_link1" />
    <child
      link="left_finger2_link2" />
    <axis
      xyz="-1 0 0" />
    <limit
      lower="-0.37"
      upper="0.37"
      effort="0.1822"
      velocity="8.115" />
  </joint>
  <link
    name="left_finger2_link3">
    <inertial><origin xyz="-0.00112187305056449 -6.72383091306211e-05 0.0157188385130449" rpy="0 0 0"/><mass value="0.0165"/><inertia ixx="1.47e-06" ixy="0.0" ixz="3e-08" iyy="1.44e-06" iyz="0.0" izz="4.5e-07"/></inertial>
    <visual>
      <origin
        xyz="0 0 0"
        rpy="0 0 0" />
      <geometry>
        <mesh
          filename="meshes/left/left_finger2_link3.STL" />
      </geometry>
      <material
        name="">
        <color
          rgba="0.627450980392157 0.627450980392157 0.627450980392157 1" />
      </material>
    </visual>
    <collision>
      <origin
        xyz="0 0 0"
        rpy="0 0 0" />
      <geometry>
        <mesh
          filename="meshes/left/left_finger2_link3.STL" />
      </geometry>
    </collision>
  </link>
  <joint
    name="left_finger2_joint3"
    type="fixed">
    <origin
      xyz="-0.00312502624735005 0.000100282455430194 0.0436176874512652"
      rpy="0 0 0.000268612717770449" />
    <parent
      link="left_finger2_link2" />
    <child
      link="left_finger2_link3" />
    <axis
      xyz="0 1 0" />
    <limit
      lower="-0.4777"
      upper="1.5485"
      effort="0.2251"
      velocity="13.578" />
  </joint>
  <link
    name="left_finger2_link4">
    <inertial><origin xyz="-0.000894378084124292 -8.29346633020867e-05 0.00535175866484416" rpy="0 0 0"/><mass value="0.014"/><inertia ixx="9.5e-07" ixy="0.0" ixz="1.4e-07" iyy="8.6e-07" iyz="-1e-08" izz="3e-07"/></inertial>
    <visual>
      <origin
        xyz="0 0 0"
        rpy="0 0 0" />
      <geometry>
        <mesh
          filename="meshes/left/left_finger2_link4.STL" />
      </geometry>
      <material
        name="">
        <color
          rgba="0.529411764705882 0.549019607843137 0.549019607843137 1" />
      </material>
    </visual>
    <collision>
      <origin
        xyz="0 0 0"
        rpy="0 0 0" />
      <geometry>
        <mesh
          filename="meshes/left/left_finger2_link4.STL" />
      </geometry>
    </collision>
  </link>
  <joint
    name="left_finger2_joint4"
    type="fixed">
    <origin
      xyz="0 0 0.0294999999999921"
      rpy="0 0 0" />
    <parent
      link="left_finger2_link3" />
    <child
      link="left_finger2_link4" />
    <axis
      xyz="0 1 0" />
    <limit
      lower="-0.4683"
      upper="1.5753"
      effort="0.2170"
      velocity="12.863" />
  </joint>
  <link
    name="left_finger2_tip_link">
    <inertial><origin xyz="0.000717599084723131 -8.44809051070428e-06 -0.00585768176210114" rpy="0 0 0"/><mass value="0.00318"/><inertia ixx="2e-07" ixy="0.0" ixz="0.0" iyy="2.1e-07" iyz="0.0" izz="1.3e-07"/></inertial>
    <visual>
      <origin
        xyz="0 0 0"
        rpy="0 0 0" />
      <geometry>
        <mesh
          filename="meshes/left/left_finger2_tip_link.STL" />
      </geometry>
      <material
        name="">
        <color
          rgba="0.529411764705882 0.549019607843137 0.549019607843137 1" />
      </material>
    </visual>
    <collision>
      <origin
        xyz="0 0 0"
        rpy="0 0 0" />
      <geometry>
        <mesh
          filename="meshes/left/left_finger2_tip_link.STL" />
      </geometry>
    </collision>
  </link>
  <joint
    name="left_finger2_tip_fixed"
    type="fixed">
    <origin
      xyz="-0.00199999998882132 -9.99999775618474E-05 0.0239466139626726"
      rpy="0 0 0" />
    <parent
      link="left_finger2_link4" />
    <child
      link="left_finger2_tip_link" />
    <axis
      xyz="0 0 0" />
  </joint>
  <link
    name="left_finger3_link1">
    <inertial><origin xyz="-0.00135189648465354 -1.49581419299494e-08 0.000202846484209235" rpy="0 0 0"/><mass value="0.0032"/><inertia ixx="8e-08" ixy="0.0" ixz="-3e-08" iyy="7e-08" iyz="0.0" izz="8e-08"/></inertial>
    <visual>
      <origin
        xyz="0 0 0"
        rpy="0 0 0" />
      <geometry>
        <mesh
          filename="meshes/left/left_finger3_link1.STL" />
      </geometry>
      <material
        name="">
        <color
          rgba="0.627450980392157 0.627450980392157 0.627450980392157 1" />
      </material>
    </visual>
    <!-- <collision>
      <origin
        xyz="0 0 0"
        rpy="0 0 0" />
      <geometry>
        <mesh
          filename="meshes/left/left_finger3_link1.STL" />
      </geometry>
    </collision> -->
  </link>
  <joint
    name="left_finger3_joint1"
    type="fixed">
    <origin
      xyz="-0.01046 -0.0074615 0.089544"
      rpy="5.0693E-05 0 -0.00057944" />
    <parent
      link="left_palm_link" />
    <child
      link="left_finger3_link1" />
    <axis
      xyz="0 1 0" />
    <limit
      lower="-0.1644"
      upper="1.5516"
      effort="0.6494"
      velocity="8.203" />
  </joint>
  <link
    name="left_finger3_link2">
    <inertial><origin xyz="-0.00633780329162388 3.07421349281852e-06 0.0204364275125137" rpy="0 0 0"/><mass value="0.033"/><inertia ixx="6.31e-06" ixy="0.0" ixz="-1.6e-07" iyy="6.34e-06" iyz="0.0" izz="8.9e-07"/></inertial>
    <visual>
      <origin
        xyz="0 0 0"
        rpy="0 0 0" />
      <geometry>
        <mesh
          filename="meshes/left/left_finger3_link2.STL" />
      </geometry>
      <material
        name="">
        <color
          rgba="0.627450980392157 0.627450980392157 0.627450980392157 1" />
      </material>
    </visual>
    <collision>
      <origin
        xyz="0 0 0"
        rpy="0 0 0" />
      <geometry>
        <mesh
          filename="meshes/left/left_finger3_link2.STL" />
      </geometry>
    </collision>
  </link>
  <joint
    name="left_finger3_joint2"
    type="fixed">
    <origin
      xyz="0.000224188923157675 0 0.00403489896760838"
      rpy="0 -0.0872664630099629 0" />
    <parent
      link="left_finger3_link1" />
    <child
      link="left_finger3_link2" />
    <axis
      xyz="-1 0 0" />
    <limit
      lower="-0.37"
      upper="0.37"
      effort="0.1827"
      velocity="8.115" />
  </joint>
  <link
    name="left_finger3_link3">
    <inertial><origin xyz="-0.00112187206031908 -6.72195699478878e-05 0.0157188383883545" rpy="0 0 0"/><mass value="0.0165"/><inertia ixx="1.47e-06" ixy="0.0" ixz="3e-08" iyy="1.44e-06" iyz="0.0" izz="4.5e-07"/></inertial>
    <visual>
      <origin
        xyz="0 0 0"
        rpy="0 0 0" />
      <geometry>
        <mesh
          filename="meshes/left/left_finger3_link3.STL" />
      </geometry>
      <material
        name="">
        <color
          rgba="0.627450980392157 0.627450980392157 0.627450980392157 1" />
      </material>
    </visual>
    <collision>
      <origin
        xyz="0 0 0"
        rpy="0 0 0" />
      <geometry>
        <mesh
          filename="meshes/left/left_finger3_link3.STL" />
      </geometry>
    </collision>
  </link>
  <joint
    name="left_finger3_joint3"
    type="fixed">
    <origin
      xyz="-0.00312502618421547 0.000100282625113788 0.0436176874508615"
      rpy="0 0 0.000268612717747223" />
    <parent
      link="left_finger3_link2" />
    <child
      link="left_finger3_link3" />
    <axis
      xyz="0 1 0" />
    <limit
      lower="-0.4739"
      upper="1.5512"
      effort="0.2078"
      velocity="13.578" />
  </joint>
  <link
    name="left_finger3_link4">
    <inertial><origin xyz="-0.000894360550804676 -8.29500264891304e-05 0.00535176646607979" rpy="0 0 0"/><mass value="0.014"/><inertia ixx="9.5e-07" ixy="0.0" ixz="1.4e-07" iyy="8.6e-07" iyz="-1e-08" izz="3e-07"/></inertial>
    <visual>
      <origin
        xyz="0 0 0"
        rpy="0 0 0" />
      <geometry>
        <mesh
          filename="meshes/left/left_finger3_link4.STL" />
      </geometry>
      <material
        name="">
        <color
          rgba="0.529411764705882 0.549019607843137 0.549019607843137 1" />
      </material>
    </visual>
    <collision>
      <origin
        xyz="0 0 0"
        rpy="0 0 0" />
      <geometry>
        <mesh
          filename="meshes/left/left_finger3_link4.STL" />
      </geometry>
    </collision>
  </link>
  <joint
    name="left_finger3_joint4"
    type="fixed">
    <origin
      xyz="0 0 0.0294999999999998"
      rpy="0 0 0" />
    <parent
      link="left_finger3_link3" />
    <child
      link="left_finger3_link4" />
    <axis
      xyz="0 1 0" />
    <limit
      lower="-0.4684"
      upper="1.5745"
      effort="0.2018"
      velocity="12.863" />
  </joint>
  <link
    name="left_finger3_tip_link">
    <inertial><origin xyz="0.000762258859382664 -7.6173785743764e-07 -0.00585762976136608" rpy="0 0 0"/><mass value="0.00318"/><inertia ixx="2e-07" ixy="0.0" ixz="0.0" iyy="2.1e-07" iyz="0.0" izz="1.3e-07"/></inertial>
    <visual>
      <origin
        xyz="0 0 0"
        rpy="0 0 0" />
      <geometry>
        <mesh
          filename="meshes/left/left_finger3_tip_link.STL" />
      </geometry>
      <material
        name="">
        <color
          rgba="0.529411764705882 0.549019607843137 0.549019607843137 1" />
      </material>
    </visual>
    <collision>
      <origin
        xyz="0 0 0"
        rpy="0 0 0" />
      <geometry>
        <mesh
          filename="meshes/left/left_finger3_tip_link.STL" />
      </geometry>
    </collision>
  </link>
  <joint
    name="left_finger3_tip_fixed"
    type="fixed">
    <origin
      xyz="-0.00199999998882053 -9.99999999926624E-05 0.0239466139625789"
      rpy="0 0 0" />
    <parent
      link="left_finger3_link4" />
    <child
      link="left_finger3_tip_link" />
    <axis
      xyz="0 0 0" />
  </joint>
  <link
    name="left_finger4_link1">
    <inertial><origin xyz="-0.00135118675339803 -9.65326286614387e-09 0.000207528544014832" rpy="0 0 0"/><mass value="0.0032"/><inertia ixx="8e-08" ixy="0.0" ixz="-3e-08" iyy="7e-08" iyz="0.0" izz="8e-08"/></inertial>
    <visual>
      <origin
        xyz="0 0 0"
        rpy="0 0 0" />
      <geometry>
        <mesh
          filename="meshes/left/left_finger4_link1.STL" />
      </geometry>
      <material
        name="">
        <color
          rgba="0.627450980392157 0.627450980392157 0.627450980392157 1" />
      </material>
    </visual>
    <!-- <collision>
      <origin
        xyz="0 0 0"
        rpy="0 0 0" />
      <geometry>
        <mesh
          filename="meshes/left/left_finger4_link1.STL" />
      </geometry>
    </collision> -->
  </link>
  <joint
    name="left_finger4_joint1"
    type="fixed">
    <origin
      xyz="-0.0076649 0.013712 0.084429"
      rpy="-0.090059 0 -0.054679" />
    <parent
      link="left_palm_link" />
    <child
      link="left_finger4_link1" />
    <axis
      xyz="0 1 0" />
    <limit
      lower="-0.1554"
      upper="1.5585"
      effort="0.6389"
      velocity="8.203" />
  </joint>
  <link
    name="left_finger4_link2">
    <inertial><origin xyz="-0.00452747286008461 0.0002141653801618 0.0209110368688094" rpy="0 0 0"/><mass value="0.033"/><inertia ixx="6.31e-06" ixy="0.0" ixz="-1.6e-07" iyy="6.34e-06" iyz="0.0" izz="8.9e-07"/></inertial>
    <visual>
      <origin
        xyz="0 0 0"
        rpy="0 0 0" />
      <geometry>
        <mesh
          filename="meshes/left/left_finger4_link2.STL" />
      </geometry>
      <material
        name="">
        <color
          rgba="0.627450980392157 0.627450980392157 0.627450980392157 1" />
      </material>
    </visual>
    <collision>
      <origin
        xyz="0 0 0"
        rpy="0 0 0" />
      <geometry>
        <mesh
          filename="meshes/left/left_finger4_link2.STL" />
      </geometry>
    </collision>
  </link>
  <joint
    name="left_finger4_joint2"
    type="fixed">
    <origin
      xyz="0.000238272023819444 0 0.00403409169489746"
      rpy="0 -0.0837758044893524 0" />
    <parent
      link="left_finger4_link1" />
    <child
      link="left_finger4_link2" />
    <axis
      xyz="-1 0 0" />
    <limit
      lower="-0.37"
      upper="0.37"
      effort="0.1832"
      velocity="8.115" />
  </joint>
  <link
    name="left_finger4_link3">
    <inertial><origin xyz="-0.00112187686014802 -6.72060755895765e-05 0.015718842473584" rpy="0 0 0"/><mass value="0.0165"/><inertia ixx="1.47e-06" ixy="0.0" ixz="3e-08" iyy="1.44e-06" iyz="0.0" izz="4.5e-07"/></inertial>
    <visual>
      <origin
        xyz="0 0 0"
        rpy="0 0 0" />
      <geometry>
        <mesh
          filename="meshes/left/left_finger4_link3.STL" />
      </geometry>
      <material
        name="">
        <color
          rgba="0.627450980392157 0.627450980392157 0.627450980392157 1" />
      </material>
    </visual>
    <collision>
      <origin
        xyz="0 0 0"
        rpy="0 0 0" />
      <geometry>
        <mesh
          filename="meshes/left/left_finger4_link3.STL" />
      </geometry>
    </collision>
  </link>
  <joint
    name="left_finger4_joint3"
    type="fixed">
    <origin
      xyz="-0.00312502629370909 0.000100282441161618 0.0436176874512648"
      rpy="0 0 0.000268623287696204" />
    <parent
      link="left_finger4_link2" />
    <child
      link="left_finger4_link3" />
    <axis
      xyz="0 1 0" />
    <limit
      lower="-0.4765"
      upper="1.5487"
      effort="0.2249"
      velocity="13.578" />
  </joint>
  <link
    name="left_finger4_link4">
    <inertial><origin xyz="-0.000894364002322151 -8.29585181423027e-05 0.00535176963985756" rpy="0 0 0"/><mass value="0.014"/><inertia ixx="9.5e-07" ixy="0.0" ixz="1.4e-07" iyy="8.6e-07" iyz="-1e-08" izz="3e-07"/></inertial>
    <visual>
      <origin
        xyz="0 0 0"
        rpy="0 0 0" />
      <geometry>
        <mesh
          filename="meshes/left/left_finger4_link4.STL" />
      </geometry>
      <material
        name="">
        <color
          rgba="0.529411764705882 0.549019607843137 0.549019607843137 1" />
      </material>
    </visual>
    <collision>
      <origin
        xyz="0 0 0"
        rpy="0 0 0" />
      <geometry>
        <mesh
          filename="meshes/left/left_finger4_link4.STL" />
      </geometry>
    </collision>
  </link>
  <joint
    name="left_finger4_joint4"
    type="fixed">
    <origin
      xyz="0 0 0.0295000000000005"
      rpy="0 0 0" />
    <parent
      link="left_finger4_link3" />
    <child
      link="left_finger4_link4" />
    <axis
      xyz="0 1 0" />
    <limit
      lower="-0.4777"
      upper="1.5634"
      effort="0.2044"
      velocity="12.863" />
  </joint>
  <link
    name="left_finger4_tip_link">
    <inertial><origin xyz="0.00076005480047972 -1.77864189068594e-05 -0.00585759702543506" rpy="0 0 0"/><mass value="0.00318"/><inertia ixx="2e-07" ixy="0.0" ixz="0.0" iyy="2.1e-07" iyz="0.0" izz="1.3e-07"/></inertial>
    <visual>
      <origin
        xyz="0 0 0"
        rpy="0 0 0" />
      <geometry>
        <mesh
          filename="meshes/left/left_finger4_tip_link.STL" />
      </geometry>
      <material
        name="">
        <color
          rgba="0.529411764705882 0.549019607843137 0.549019607843137 1" />
      </material>
    </visual>
    <collision>
      <origin
        xyz="0 0 0"
        rpy="0 0 0" />
      <geometry>
        <mesh
          filename="meshes/left/left_finger4_tip_link.STL" />
      </geometry>
    </collision>
  </link>
  <joint
    name="left_finger4_tip_fixed"
    type="fixed">
    <origin
      xyz="-0.00199999999999928 -9.99999794204474E-05 0.0239466139617312"
      rpy="0 0 0" />
    <parent
      link="left_finger4_link4" />
    <child
      link="left_finger4_tip_link" />
    <axis
      xyz="0 0 0" />
  </joint>
  <link
    name="left_finger5_link1">
    <inertial><origin xyz="-0.00135329447496806 -2.35789230987327e-08 0.000193346570700414" rpy="0 0 0"/><mass value="0.0032"/><inertia ixx="8e-08" ixy="0.0" ixz="-3e-08" iyy="7e-08" iyz="0.0" izz="8e-08"/></inertial>
    <visual>
      <origin
        xyz="0 0 0"
        rpy="0 0 0" />
      <geometry>
        <mesh
          filename="meshes/left/left_finger5_link1.STL" />
      </geometry>
      <material
        name="">
        <color
          rgba="0.627450980392157 0.627450980392157 0.627450980392157 1" />
      </material>
    </visual>
    <!-- <collision>
      <origin
        xyz="0 0 0"
        rpy="0 0 0" />
      <geometry>
        <mesh
          filename="meshes/left/left_finger5_link1.STL" />
      </geometry>
    </collision> -->
  </link>
  <joint
    name="left_finger5_joint1"
    type="fixed">
    <origin
      xyz="-0.00226865105948153 0.0340011106647822 0.0742813381432918"
      rpy="-0.191650218499317 0 -0.175676455157885" />
    <parent
      link="left_palm_link" />
    <child
      link="left_finger5_link1" />
    <axis
      xyz="0 1 0" />
    <limit
      lower="-0.1626"
      upper="1.5585"
      effort="0.6441"
      velocity="8.203" />
  </joint>
  <link
    name="left_finger5_link2">
    <inertial><origin xyz="-0.00453252784898839 4.36745136160599e-07 0.0209110443867004" rpy="0 0 0"/><mass value="0.033"/><inertia ixx="6.31e-06" ixy="0.0" ixz="-1.6e-07" iyy="6.34e-06" iyz="0.0" izz="8.9e-07"/></inertial>
    <visual>
      <origin
        xyz="0 0 0"
        rpy="0 0 0" />
      <geometry>
        <mesh
          filename="meshes/left/left_finger5_link2.STL" />
      </geometry>
      <material
        name="">
        <color
          rgba="0.627450980392157 0.627450980392157 0.627450980392157 1" />
      </material>
    </visual>
    <collision>
      <origin
        xyz="0 0 0"
        rpy="0 0 0" />
      <geometry>
        <mesh
          filename="meshes/left/left_finger5_link2.STL" />
      </geometry>
    </collision>
  </link>
  <joint
    name="left_finger5_joint2"
    type="fixed">
    <origin
      xyz="0.000196015009673409 0 0.00403636545307588"
      rpy="0 -0.0942477800158131 0" />
    <parent
      link="left_finger5_link1" />
    <child
      link="left_finger5_link2" />
    <axis
      xyz="-1 0 0" />
    <limit
      lower="-0.37"
      upper="0.37"
      effort="0.1798"
      velocity="8.115" />
  </joint>
  <link
    name="left_finger5_link3">
    <inertial><origin xyz="-0.00112187608632448 -6.71933271821773e-05 0.0157188470383108" rpy="0 0 0"/><mass value="0.0165"/><inertia ixx="1.47e-06" ixy="0.0" ixz="3e-08" iyy="1.44e-06" iyz="0.0" izz="4.5e-07"/></inertial>
    <visual>
      <origin
        xyz="0 0 0"
        rpy="0 0 0" />
      <geometry>
        <mesh
          filename="meshes/left/left_finger5_link3.STL" />
      </geometry>
      <material
        name="">
        <color
          rgba="0.627450980392157 0.627450980392157 0.627450980392157 1" />
      </material>
    </visual>
    <collision>
      <origin
        xyz="0 0 0"
        rpy="0 0 0" />
      <geometry>
        <mesh
          filename="meshes/left/left_finger5_link3.STL" />
      </geometry>
    </collision>
  </link>
  <joint
    name="left_finger5_joint3"
    type="fixed">
    <origin
      xyz="-0.00312502637316564 0.000100282626826854 0.0436176864544762"
      rpy="0 0 0.000268612717748753" />
    <parent
      link="left_finger5_link2" />
    <child
      link="left_finger5_link3" />
    <axis
      xyz="0 1 0" />
    <limit
      lower="-0.4768"
      upper="1.5490"
      effort="0.2384"
      velocity="13.578" />
  </joint>
  <link
    name="left_finger5_link4">
    <inertial><origin xyz="-0.000894376068463737 -8.29587184504807e-05 0.00535176561210726" rpy="0 0 0"/><mass value="0.014"/><inertia ixx="9.5e-07" ixy="0.0" ixz="1.4e-07" iyy="8.6e-07" iyz="-1e-08" izz="3e-07"/></inertial>
    <visual>
      <origin
        xyz="0 0 0"
        rpy="0 0 0" />
      <geometry>
        <mesh
          filename="meshes/left/left_finger5_link4.STL" />
      </geometry>
      <material
        name="">
        <color
          rgba="0.529411764705882 0.549019607843137 0.549019607843137 1" />
      </material>
    </visual>
    <collision>
      <origin
        xyz="0 0 0"
        rpy="0 0 0" />
      <geometry>
        <mesh
          filename="meshes/left/left_finger5_link4.STL" />
      </geometry>
    </collision>
  </link>
  <joint
    name="left_finger5_joint4"
    type="fixed">
    <origin
      xyz="0 0 0.0295000009963936"
      rpy="0 0 0" />
    <parent
      link="left_finger5_link3" />
    <child
      link="left_finger5_link4" />
    <axis
      xyz="0 1 0" />
    <limit
      lower="-0.4683"
      upper="1.5735"
      effort="0.1866"
      velocity="12.863" />
  </joint>
  <link
    name="left_finger5_tip_link">
    <inertial><origin xyz="0.000743020095030855 4.15556515511589e-06 -0.00585759127452531" rpy="0 0 0"/><mass value="0.00318"/><inertia ixx="2e-07" ixy="0.0" ixz="0.0" iyy="2.1e-07" iyz="0.0" izz="1.3e-07"/></inertial>
    <visual>
      <origin
        xyz="0 0 0"
        rpy="0 0 0" />
      <geometry>
        <mesh
          filename="meshes/left/left_finger5_tip_link.STL" />
      </geometry>
      <material
        name="">
        <color
          rgba="0.529411764705882 0.549019607843137 0.549019607843137 1" />
      </material>
    </visual>
    <collision>
      <origin
        xyz="0 0 0"
        rpy="0 0 0" />
      <geometry>
        <mesh
          filename="meshes/left/left_finger5_tip_link.STL" />
      </geometry>
    </collision>
  </link>
  <joint
    name="left_finger5_tip_fixed"
    type="fixed">
    <origin
      xyz="-0.00200000001120192 -9.99999794204162E-05 0.0239466139607956"
      rpy="0 0 0" />
    <parent
      link="left_finger5_link4" />
    <child
      link="left_finger5_tip_link" />
    <axis
      xyz="0 0 0" />
  </joint>
  <link name="right_shoulder_pitch_link">
    <inertial>
      <origin xyz="0 -0.035892 -0.011628" rpy="0 0 0"/>
      <mass value="0.718"/>
      <inertia ixx="0.0004291" ixy="9.2E-06" ixz="6.4E-06" iyy="0.000453" iyz="-2.26E-05" izz="0.000423"/>
    </inertial>
    <visual>
      <origin xyz="0 0 0" rpy="0 0 0"/>
      <geometry>
        <mesh filename="meshes/g1/right_shoulder_pitch_link.STL"/>
      </geometry>
      <material name="white"/>
    </visual>
  </link>
  <joint name="right_shoulder_pitch_joint" type="revolute">
    <origin xyz="0.0039563 -0.10021 0.24778" rpy="-0.27931 5.4949E-05 0.00019159"/>
    <parent link="torso_link"/>
    <child link="right_shoulder_pitch_link"/>
    <axis xyz="0 1 0"/>
    <limit lower="-3.0892" upper="2.6704" effort="25" velocity="37"/>
  </joint>
  <link name="right_shoulder_roll_link">
    <inertial>
      <origin xyz="-0.000227 -0.00727 -0.063243" rpy="0 0 0"/>
      <mass value="0.643"/>
      <inertia ixx="0.0006177" ixy="1E-06" ixz="8.7E-06" iyy="0.0006912" iyz="5.3E-06" izz="0.0003894"/>
    </inertial>
    <visual>
      <origin xyz="0 0 0" rpy="0 0 0"/>
      <geometry>
        <mesh filename="meshes/g1/right_shoulder_roll_link.STL"/>
      </geometry>
      <material name="white"/>
    </visual>
  </link>
  <joint name="right_shoulder_roll_joint" type="revolute">
    <origin xyz="0 -0.038 -0.013831" rpy="0.27925 0 0"/>
    <parent link="right_shoulder_pitch_link"/>
    <child link="right_shoulder_roll_link"/>
    <axis xyz="1 0 0"/>
    <limit lower="-2.2515" upper="1.5882" effort="25" velocity="37"/>
  </joint>
  <link name="right_shoulder_yaw_link">
    <inertial>
      <origin xyz="0.010773 0.002949 -0.072009" rpy="0 0 0"/>
      <mass value="0.734"/>
      <inertia ixx="0.0009988" ixy="-7.9E-06" ixz="0.0001412" iyy="0.0010605" iyz="2.86E-05" izz="0.0004354"/>
    </inertial>
    <visual>
      <origin xyz="0 0 0" rpy="0 0 0"/>
      <geometry>
        <mesh filename="meshes/g1/right_shoulder_yaw_link.STL"/>
      </geometry>
      <material name="white"/>
    </visual>
    <collision>
      <origin xyz="0 0 -0.015" rpy="3.1416 0 0"/>
      <geometry>
        <cylinder radius="0.035" length="0.13"/>
      </geometry>
    </collision>
  </link>
  <joint name="right_shoulder_yaw_joint" type="revolute">
    <origin xyz="0 -0.00624 -0.1032" rpy="0 0 0"/>
    <parent link="right_shoulder_roll_link"/>
    <child link="right_shoulder_yaw_link"/>
    <axis xyz="0 0 1"/>
    <limit lower="-2.618" upper="2.618" effort="25" velocity="37"/>
  </joint>
  <link name="right_elbow_link">
    <inertial>
      <origin xyz="0.064956 -0.004454 -0.010062" rpy="0 0 0"/>
      <mass value="0.6"/>
      <inertia ixx="0.0002891" ixy="-6.53E-05" ixz="1.72E-05" iyy="0.0004152" iyz="5.6E-06" izz="0.0004197"/>
    </inertial>
    <visual>
      <origin xyz="0 0 0" rpy="0 0 0"/>
      <geometry>
        <mesh filename="meshes/g1/right_elbow_link.STL"/>
      </geometry>
      <material name="white"/>
    </visual>
    <collision>
      <origin xyz="0.055 0 -0.01" rpy="0 -1.5708 0"/>
      <geometry>
        <cylinder radius="0.035" length="0.13"/>
      </geometry>
    </collision>
  </link>
  <joint name="right_elbow_joint" type="revolute">
    <origin xyz="0.015783 0 -0.080518" rpy="0 0 0"/>
    <parent link="right_shoulder_yaw_link"/>
    <child link="right_elbow_link"/>
    <axis xyz="0 1 0"/>
    <limit lower="-1.0472" upper="2.0944" effort="25" velocity="37"/>
  </joint>
  <joint name="right_wrist_roll_joint" type="revolute">
    <origin xyz="0.100 -0.00188791 -0.010" rpy="0 0 0"/>
    <axis xyz="1 0 0"/>
    <parent link="right_elbow_link"/>
    <child link="right_wrist_roll_link"/>
    <limit effort="25" velocity="37" lower="-1.972222054" upper="1.972222054"/>
  </joint>
  <link name="right_wrist_roll_link">
    <inertial>
      <origin xyz="0.01713944778 -0.00053759094 0.00000048864" rpy="0 0 0"/>
      <mass value="0.08544498"/>
      <inertia ixx="0.00004821544023" ixy="0.00000424511021" ixz="0.00000000510599" iyy="0.00003722899093" iyz="0.00000000123525" izz="0.00005482106541"/>
    </inertial>
    <visual>
      <origin xyz="0 0 0" rpy="0 0 0"/>
      <geometry>
        <mesh filename="meshes/g1/right_wrist_roll_link.STL"/>
      </geometry>
      <material name="white"/>
    </visual>
  </link>
  <joint name="right_wrist_pitch_joint" type="revolute">
    <origin xyz="0.038 0 0" rpy="0 0 0"/>
    <axis xyz="0 1 0"/>
    <parent link="right_wrist_roll_link"/>
    <child link="right_wrist_pitch_link"/>
    <limit effort="5" velocity="22" lower="-1.614429558" upper="1.614429558"/>
  </joint>
  <link name="right_wrist_pitch_link">
    <inertial>
      <origin xyz="0.02299989837 0.00111685314 -0.00111658096" rpy="0 0 0"/>
      <mass value="0.48404956"/>
      <inertia ixx="0.00016579646273" ixy="0.00001231206746" ixz="0.00001231699194" iyy="0.00042954057410" iyz="-0.00000081417712" izz="0.00042953697654"/>
    </inertial>
    <visual>
      <origin xyz="0 0 0" rpy="0 0 0"/>
      <geometry>
        <mesh filename="meshes/g1/right_wrist_pitch_link.STL"/>
      </geometry>
      <material name="white"/>
    </visual>
  </link>
  <joint name="right_wrist_yaw_joint" type="revolute">
    <origin xyz="0.046 0 0" rpy="0 0 0"/>
    <axis xyz="0 0 1"/>
    <parent link="right_wrist_pitch_link"/>
    <child link="right_wrist_yaw_link"/>
    <limit effort="5" velocity="22" lower="-1.614429558" upper="1.614429558"/>
  </joint>
  <link name="right_wrist_yaw_link">
    <inertial>
      <origin xyz="0.02200381568 -0.00049485096 0.00053861123" rpy="0 0 0"/>
      <mass value="0.08457647"/>
      <inertia ixx="0.00004929128828" ixy="0.00000045735494" ixz="0.00000445867591" iyy="0.00005973338134" iyz="-0.00000043217198" izz="0.00003928083826"/>
    </inertial>
    <visual>
      <origin xyz="0 0 0" rpy="0 0 0"/>
      <geometry>
        <mesh filename="meshes/g1/right_wrist_yaw_link.STL"/>
      </geometry>
      <material name="white"/>
    </visual>
    <!-- <collision>
            <origin xyz="0.075 0 0" rpy="0 -1.5708 0"/>
            <geometry>
                <cylinder radius="0.05" length="0.05"/>
            </geometry>
        </collision> -->
  </link>
  <joint name="right_hand_palm_joint" type="fixed">
    <origin xyz="0.0415 -0.003 0" rpy="-1.5708 3.1416 -1.5708"/>
    <parent link="right_wrist_yaw_link"/>
    <child link="right_palm_link"/>
  </joint>
  <link
    name="right_palm_link">
    <inertial><origin xyz="-0.0029795 0.00045572 0.036654" rpy="0 0 0"/><mass value="0.16914"/><inertia ixx="0.00014" ixy="2.54e-06" ixz="6.91e-06" iyy="9.47e-05" iyz="-6.63e-06" izz="6e-05"/></inertial>
    <visual>
      <origin
        xyz="0 0 0"
        rpy="0 0 0" />
      <geometry>
        <mesh
          filename="meshes/right/right_palm_link.STL" />
      </geometry>
      <material
        name="">
        <color
          rgba="0.89804 0.91765 0.92941 1" />
      </material>
    </visual>
    <collision>
      <origin
        xyz="0 0 0"
        rpy="0 0 0" />
      <geometry>
        <mesh
          filename="meshes/right/right_palm_link.STL" />
      </geometry>
    </collision>
  </link>
  <link
    name="right_finger1_link1">
    <inertial><origin xyz="-0.0024628 -0.0014428 0.0077802" rpy="0 0 0"/><mass value="0.0075"/><inertia ixx="3.2e-07" ixy="-2e-08" ixz="0.0" iyy="3e-07" iyz="4e-08" izz="2.3e-07"/></inertial>
    <visual>
      <origin
        xyz="0 0 0"
        rpy="0 0 0" />
      <geometry>
        <mesh
          filename="meshes/right/right_finger1_link1.STL" />
      </geometry>
      <material
        name="">
        <color
          rgba="0.89804 0.91765 0.92941 1" />
      </material>
    </visual>
    <!-- <collision>
      <origin
        xyz="0 0 0"
        rpy="0 0 0" />
      <geometry>
        <mesh
          filename="meshes/right/right_finger1_link1.STL" />
      </geometry>
    </collision> -->
  </link>
  <joint
    name="right_finger1_joint1"
    type="fixed">
    <origin
      xyz="0.0085244 0.020575 0.028712"
      rpy="-1.328 -0.37161 -0.7307" />
    <parent
      link="right_palm_link" />
    <child
      link="right_finger1_link1" />
    <axis
      xyz="-0 1 -0" />
    <limit
      lower="0.0475"
      upper="1.6033"
      effort="0.4452"
      velocity="8.58701992" />
  </joint>
  <link
    name="right_finger1_link2">
    <inertial><origin xyz="0.0011196 -1.2405e-05 0.015663" rpy="0 0 0"/><mass value="0.0248"/><inertia ixx="2.76e-06" ixy="2e-08" ixz="1e-08" iyy="2.81e-06" iyz="2e-08" izz="6.8e-07"/></inertial>
    <visual>
      <origin
        xyz="0 0 0"
        rpy="0 0 0" />
      <geometry>
        <mesh
          filename="meshes/right/right_finger1_link2.STL" />
      </geometry>
      <material
        name="">
        <color
          rgba="0.89804 0.91765 0.92941 1" />
      </material>
    </visual>
    <collision>
      <origin
        xyz="0 0 0"
        rpy="0 0 0" />
      <geometry>
        <mesh
          filename="meshes/right/right_finger1_link2.STL" />
      </geometry>
    </collision>
  </link>
  <joint
    name="right_finger1_joint2"
    type="fixed">
    <origin
      xyz="-0.0047549 -0.0060191 0.014132"
      rpy="-0.57428 -0.23677 1.8034" />
    <parent
      link="right_finger1_link1" />
    <child
      link="right_finger1_link2" />
    <axis
      xyz="-0 -1 -0" />
    <limit
      lower="-0.1387"
      upper="0.9324"
      effort="0.4259"
      velocity="11.10029404" />
  </joint>
  <link
    name="right_finger1_link3">
    <inertial><origin xyz="-0.0011235 -1.579e-05 0.013056" rpy="0 0 0"/><mass value="0.0165"/><inertia ixx="1.46e-06" ixy="0.0" ixz="-2e-08" iyy="1.42e-06" iyz="0.0" izz="4.5e-07"/></inertial>
    <visual>
      <origin
        xyz="0 0 0"
        rpy="0 0 0" />
      <geometry>
        <mesh
          filename="meshes/right/right_finger1_link3.STL" />
      </geometry>
      <material
        name="">
        <color
          rgba="0.89804 0.91765 0.92941 1" />
      </material>
    </visual>
    <collision>
      <origin
        xyz="0 0 0"
        rpy="0 0 0" />
      <geometry>
        <mesh
          filename="meshes/right/right_finger1_link3.STL" />
      </geometry>
    </collision>
  </link>
  <joint
    name="right_finger1_joint3"
    type="fixed">
    <origin
      xyz="0.00018873 -0.0009916 0.034664"
      rpy="0.049049 0.017311 -1.9085" />
    <parent
      link="right_finger1_link2" />
    <child
      link="right_finger1_link3" />
    <axis
      xyz="0 1 0" />
    <limit
      lower="-0.4642"
      upper="1.5623"
      effort="0.1888"
      velocity="12.86307659" />
  </joint>
  <link
    name="right_finger1_link4">
    <inertial><origin xyz="-0.0011922 0.00023589 0.0082118" rpy="0 0 0"/><mass value="0.0165"/><inertia ixx="1.18e-06" ixy="0.0" ixz="1.2e-07" iyy="1.25e-06" iyz="0.0" izz="5.1e-07"/></inertial>
    <visual>
      <origin
        xyz="0 0 0"
        rpy="0 0 0" />
      <geometry>
        <mesh
          filename="meshes/right/right_finger1_link4.STL" />
      </geometry>
      <material
        name="">
        <color
          rgba="0.89804 0.91765 0.92941 1" />
      </material>
    </visual>
    <collision>
      <origin
        xyz="0 0 0"
        rpy="0 0 0" />
      <geometry>
        <mesh
          filename="meshes/right/right_finger1_link4.STL" />
      </geometry>
    </collision>
  </link>
  <joint
    name="right_finger1_joint4"
    type="fixed">
    <origin
      xyz="0 -0.00025 0.0295"
      rpy="0 0 0" />
    <parent
      link="right_finger1_link3" />
    <child
      link="right_finger1_link4" />
    <axis
      xyz="0 1 0" />
    <limit
      lower="-0.4699"
      upper="1.5568"
      effort="0.1468"
      velocity="13.57866158" />
  </joint>
  <link
    name="right_finger1_tip_link">
    <inertial><origin xyz="-0.00018237 -3.9481e-06 -0.0041777" rpy="0 0 0"/><mass value="0.0041"/><inertia ixx="5.5e-07" ixy="0.0" ixz="2e-08" iyy="5.2e-07" iyz="0.0" izz="2.7e-07"/></inertial>
    <visual>
      <origin
        xyz="0 0 0"
        rpy="0 0 0" />
      <geometry>
        <mesh
          filename="meshes/right/right_finger1_tip_link.STL" />
      </geometry>
      <material
        name="">
        <color
          rgba="0.89804 0.91765 0.92941 1" />
      </material>
    </visual>
    <collision>
      <origin
        xyz="0 0 0"
        rpy="0 0 0" />
      <geometry>
        <mesh
          filename="meshes/right/right_finger1_tip_link.STL" />
      </geometry>
    </collision>
  </link>
  <joint
    name="right_finger1_tip_fixed"
    type="fixed">
    <origin
      xyz="-0.0011048 0.00023218 0.0283"
      rpy="0 0 0" />
    <parent
      link="right_finger1_link4" />
    <child
      link="right_finger1_tip_link" />
    <axis
      xyz="0 0 0" />
  </joint>
  <link
    name="right_finger2_link1">
    <inertial><origin xyz="-0.0013291 -3.2911e-08 0.00031987" rpy="0 0 0"/><mass value="0.0032"/><inertia ixx="8e-08" ixy="0.0" ixz="-3e-08" iyy="7e-08" iyz="0.0" izz="8e-08"/></inertial>
    <visual>
      <origin
        xyz="0 0 0"
        rpy="0 0 0" />
      <geometry>
        <mesh
          filename="meshes/right/right_finger2_link1.STL" />
      </geometry>
      <material
        name="">
        <color
          rgba="0.89804 0.91765 0.92941 1" />
      </material>
    </visual>
    <!-- <collision>
      <origin
        xyz="0 0 0"
        rpy="0 0 0" />
      <geometry>
        <mesh
          filename="meshes/right/right_finger2_link1.STL" />
      </geometry>
    </collision> -->
  </link>
  <joint
    name="right_finger2_joint1"
    type="fixed">
    <origin
      xyz="-0.0058701 0.029434 0.091917"
      rpy="-0.11071 -0.071139 -0.21822" />
    <parent
      link="right_palm_link" />
    <child
      link="right_finger2_link1" />
    <axis
      xyz="0 1 0" />
    <limit
      lower="-0.1585"
      upper="1.5604"
      effort="0.6188"
      velocity="8.203047484" />
  </joint>
  <link
    name="right_finger2_link2">
    <inertial><origin xyz="-0.0061577 -4.1189e-07 0.020911" rpy="0 0 0"/><mass value="0.033"/><inertia ixx="6.31e-06" ixy="0.0" ixz="-1.6e-07" iyy="6.34e-06" iyz="0.0" izz="8.9e-07"/></inertial>
    <visual>
      <origin
        xyz="0 0 0"
        rpy="0 0 0" />
      <geometry>
        <mesh
          filename="meshes/right/right_finger2_link2.STL" />
      </geometry>
      <material
        name="">
        <color
          rgba="0.89804 0.91765 0.92941 1" />
      </material>
    </visual>
    <collision>
      <origin
        xyz="0 0 0"
        rpy="0 0 0" />
      <geometry>
        <mesh
          filename="meshes/right/right_finger2_link2.STL" />
      </geometry>
    </collision>
  </link>
  <joint
    name="right_finger2_joint2"
    type="fixed">
    <origin
      xyz="0.0022 0 0.004"
      rpy="0 0 0" />
    <parent
      link="right_finger2_link1" />
    <child
      link="right_finger2_link2" />
    <axis
      xyz="-1 0 0" />
    <limit
      lower="-0.37"
      upper="0.37"
      effort="0.1822"
      velocity="8.115781022" />
  </joint>
  <link
    name="right_finger2_link3">
    <inertial><origin xyz="-0.0011668 4.1873e-06 0.026893" rpy="0 0 0"/><mass value="0.0165"/><inertia ixx="1.47e-06" ixy="0.0" ixz="3e-08" iyy="1.44e-06" iyz="0.0" izz="4.5e-07"/></inertial>
    <visual>
      <origin
        xyz="0 0 0"
        rpy="0 0 0" />
      <geometry>
        <mesh
          filename="meshes/right/right_finger2_link3.STL" />
      </geometry>
      <material
        name="">
        <color
          rgba="0.89804 0.91765 0.92941 1" />
      </material>
    </visual>
    <collision>
      <origin
        xyz="0 0 0"
        rpy="0 0 0" />
      <geometry>
        <mesh
          filename="meshes/right/right_finger2_link3.STL" />
      </geometry>
    </collision>
  </link>
  <joint
    name="right_finger2_joint3"
    type="fixed">
    <origin
      xyz="-0.0047503 0 0.043618"
      rpy="0 0 -0.00026861" />
    <parent
      link="right_finger2_link2" />
    <child
      link="right_finger2_link3" />
    <axis
      xyz="-0 1 -0" />
    <limit
      lower="-0.4777"
      upper="1.5485"
      effort="0.2251"
      velocity="12.86307659" />
  </joint>
  <link
    name="right_finger2_link4">
    <inertial><origin xyz="-0.00089438 1.7042e-05 0.0053518" rpy="0 0 0"/><mass value="0.014"/><inertia ixx="9.5e-07" ixy="0.0" ixz="1.4e-07" iyy="8.6e-07" iyz="-1e-08" izz="3e-07"/></inertial>
    <visual>
      <origin
        xyz="0 0 0"
        rpy="0 0 0" />
      <geometry>
        <mesh
          filename="meshes/right/right_finger2_link4.STL" />
      </geometry>
      <material
        name="">
        <color
          rgba="0.89804 0.91765 0.92941 1" />
      </material>
    </visual>
    <collision>
      <origin
        xyz="0 0 0"
        rpy="0 0 0" />
      <geometry>
        <mesh
          filename="meshes/right/right_finger2_link4.STL" />
      </geometry>
    </collision>
  </link>
  <joint
    name="right_finger2_joint4"
    type="fixed">
    <origin
      xyz="0 0 0.0295"
      rpy="0 0 0" />
    <parent
      link="right_finger2_link3" />
    <child
      link="right_finger2_link4" />
    <axis
      xyz="-0 1 -0" />
    <limit
      lower="-0.4683"
      upper="1.5753"
      effort="0.2170"
      velocity="13.57866158" />
  </joint>
  <link
    name="right_finger2_tip_link">
    <inertial><origin xyz="-0.00020111 3.8638e-06 -0.009311" rpy="0 0 0"/><mass value="0.00318"/><inertia ixx="2e-07" ixy="0.0" ixz="0.0" iyy="2.1e-07" iyz="0.0" izz="1.3e-07"/></inertial>
    <visual>
      <origin
        xyz="0 0 0"
        rpy="0 0 0" />
      <geometry>
        <mesh
          filename="meshes/right/right_finger2_tip_link.STL" />
      </geometry>
      <material
        name="">
        <color
          rgba="0.89804 0.91765 0.92941 1" />
      </material>
    </visual>
    <collision>
      <origin
        xyz="0 0 0"
        rpy="0 0 0" />
      <geometry>
        <mesh
          filename="meshes/right/right_finger2_tip_link.STL" />
      </geometry>
    </collision>
  </link>
  <joint
    name="right_finger2_tip_fixed"
    type="fixed">
    <origin
      xyz="-0.00105 0 0.0274"
      rpy="0 0 0" />
    <parent
      link="right_finger2_link4" />
    <child
      link="right_finger2_tip_link" />
    <axis
      xyz="0 0 0" />
  </joint>
  <link
    name="right_finger3_link1">
    <inertial><origin xyz="-0.0013291 3.4987e-09 0.00031994" rpy="0 0 0"/><mass value="0.0032"/><inertia ixx="8e-08" ixy="0.0" ixz="-3e-08" iyy="7e-08" iyz="0.0" izz="8e-08"/></inertial>
    <visual>
      <origin
        xyz="0 0 0"
        rpy="0 0 0" />
      <geometry>
        <mesh
          filename="meshes/right/right_finger3_link1.STL" />
      </geometry>
      <material
        name="">
        <color
          rgba="0.89804 0.91765 0.92941 1" />
      </material>
    </visual>
    <!-- <collision>
      <origin
        xyz="0 0 0"
        rpy="0 0 0" />
      <geometry>
        <mesh
          filename="meshes/right/right_finger3_link1.STL" />
      </geometry>
    </collision> -->
  </link>
  <joint
    name="right_finger3_joint1"
    type="fixed">
    <origin
      xyz="-0.01046 0.0074615 0.089544"
      rpy="-5.0886E-05 -0.087266 0.00058387" />
    <parent
      link="right_palm_link" />
    <child
      link="right_finger3_link1" />
    <axis
      xyz="0 1 0" />
    <limit
      lower="-0.1644"
      upper="1.5516"
      effort="0.6494"
      velocity="8.203047484" />
  </joint>
  <link
    name="right_finger3_link2">
    <inertial><origin xyz="-0.0061576 -4.1651e-07 0.020911" rpy="0 0 0"/><mass value="0.033"/><inertia ixx="6.31e-06" ixy="0.0" ixz="-1.6e-07" iyy="6.34e-06" iyz="0.0" izz="8.9e-07"/></inertial>
    <visual>
      <origin
        xyz="0 0 0"
        rpy="0 0 0" />
      <geometry>
        <mesh
          filename="meshes/right/right_finger3_link2.STL" />
      </geometry>
      <material
        name="">
        <color
          rgba="0.89804 0.91765 0.92941 1" />
      </material>
    </visual>
    <collision>
      <origin
        xyz="0 0 0"
        rpy="0 0 0" />
      <geometry>
        <mesh
          filename="meshes/right/right_finger3_link2.STL" />
      </geometry>
    </collision>
  </link>
  <joint
    name="right_finger3_joint2"
    type="fixed">
    <origin
      xyz="0.0022 0 0.004"
      rpy="0 0 0" />
    <parent
      link="right_finger3_link1" />
    <child
      link="right_finger3_link2" />
    <axis
      xyz="-1 0 0" />
    <limit
      lower="-0.37"
      upper="0.37"
      effort="0.1827"
      velocity="8.115781022" />
  </joint>
  <link
    name="right_finger3_link3">
    <inertial><origin xyz="-0.0011214 4.331e-06 0.015763" rpy="0 0 0"/><mass value="0.0165"/><inertia ixx="1.47e-06" ixy="0.0" ixz="3e-08" iyy="1.44e-06" iyz="0.0" izz="4.5e-07"/></inertial>
    <visual>
      <origin
        xyz="0 0 0"
        rpy="0 0 0" />
      <geometry>
        <mesh
          filename="meshes/right/right_finger3_link3.STL" />
      </geometry>
      <material
        name="">
        <color
          rgba="0.89804 0.91765 0.92941 1" />
      </material>
    </visual>
    <collision>
      <origin
        xyz="0 0 0"
        rpy="0 0 0" />
      <geometry>
        <mesh
          filename="meshes/right/right_finger3_link3.STL" />
      </geometry>
    </collision>
  </link>
  <joint
    name="right_finger3_joint3"
    type="fixed">
    <origin
      xyz="-0.00475 0 0.043618"
      rpy="0 0 -0.00026861" />
    <parent
      link="right_finger3_link2" />
    <child
      link="right_finger3_link3" />
    <axis
      xyz="-0 1 -0" />
    <limit
      lower="-0.4739"
      upper="1.5512"
      effort="0.2078"
      velocity="12.86307659" />
  </joint>
  <link
    name="right_finger3_link4">
    <inertial><origin xyz="-0.00089436 1.7049e-05 0.0053518" rpy="0 0 0"/><mass value="0.014"/><inertia ixx="9.5e-07" ixy="0.0" ixz="1.4e-07" iyy="8.6e-07" iyz="-1e-08" izz="3e-07"/></inertial>
    <visual>
      <origin
        xyz="0 0 0"
        rpy="0 0 0" />
      <geometry>
        <mesh
          filename="meshes/right/right_finger3_link4.STL" />
      </geometry>
      <material
        name="">
        <color
          rgba="0.89804 0.91765 0.92941 1" />
      </material>
    </visual>
    <collision>
      <origin
        xyz="0 0 0"
        rpy="0 0 0" />
      <geometry>
        <mesh
          filename="meshes/right/right_finger3_link4.STL" />
      </geometry>
    </collision>
  </link>
  <joint
    name="right_finger3_joint4"
    type="fixed">
    <origin
      xyz="0 0 0.0295"
      rpy="0 0 0" />
    <parent
      link="right_finger3_link3" />
    <child
      link="right_finger3_link4" />
    <axis
      xyz="-0 1 -0" />
    <limit
      lower="-0.4684"
      upper="1.5745"
      effort="0.2018"
      velocity="13.57866158" />
  </joint>
  <link
    name="right_finger3_tip_link">
    <inertial><origin xyz="-0.00020328 1.4971e-06 -0.008611" rpy="0 0 0"/><mass value="0.00318"/><inertia ixx="2e-07" ixy="0.0" ixz="0.0" iyy="2.1e-07" iyz="0.0" izz="1.3e-07"/></inertial>
    <visual>
      <origin
        xyz="0 0 0"
        rpy="0 0 0" />
      <geometry>
        <mesh
          filename="meshes/right/right_finger3_tip_link.STL" />
      </geometry>
      <material
        name="">
        <color
          rgba="0.89804 0.91765 0.92941 1" />
      </material>
    </visual>
    <collision>
      <origin
        xyz="0 0 0"
        rpy="0 0 0" />
      <geometry>
        <mesh
          filename="meshes/right/right_finger3_tip_link.STL" />
      </geometry>
    </collision>
  </link>
  <joint
    name="right_finger3_tip_fixed"
    type="fixed">
    <origin
      xyz="-0.0010491 0 0.0267"
      rpy="0 0 0" />
    <parent
      link="right_finger3_link4" />
    <child
      link="right_finger3_tip_link" />
    <axis
      xyz="0 0 0" />
  </joint>
  <link
    name="right_finger4_link1">
    <inertial><origin xyz="-0.0013291 1.0048e-08 0.00031995" rpy="0 0 0"/><mass value="0.0032"/><inertia ixx="8e-08" ixy="0.0" ixz="-3e-08" iyy="7e-08" iyz="0.0" izz="8e-08"/></inertial>
    <visual>
      <origin
        xyz="0 0 0"
        rpy="0 0 0" />
      <geometry>
        <mesh
          filename="meshes/right/right_finger4_link1.STL" />
      </geometry>
      <material
        name="">
        <color
          rgba="0.89804 0.91765 0.92941 1" />
      </material>
    </visual>
    <!-- <collision>
      <origin
        xyz="0 0 0"
        rpy="0 0 0" />
      <geometry>
        <mesh
          filename="meshes/right/right_finger4_link1.STL" />
      </geometry>
    </collision> -->
  </link>
  <joint
    name="right_finger4_joint1"
    type="fixed">
    <origin
      xyz="-0.0076649 -0.013712 0.084429"
      rpy="0.090375 -0.083436 0.047127" />
    <parent
      link="right_palm_link" />
    <child
      link="right_finger4_link1" />
    <axis
      xyz="-0 1 -0" />
    <limit
      lower="-0.1554"
      upper="1.5585"
      effort="0.6389"
      velocity="8.203047484" />
  </joint>
  <link
    name="right_finger4_link2">
    <inertial><origin xyz="-0.0061576 -4.1601e-07 0.020911" rpy="0 0 0"/><mass value="0.033"/><inertia ixx="6.31e-06" ixy="0.0" ixz="-1.6e-07" iyy="6.34e-06" iyz="0.0" izz="8.9e-07"/></inertial>
    <visual>
      <origin
        xyz="0 0 0"
        rpy="0 0 0" />
      <geometry>
        <mesh
          filename="meshes/right/right_finger4_link2.STL" />
      </geometry>
      <material
        name="">
        <color
          rgba="0.89804 0.91765 0.92941 1" />
      </material>
    </visual>
    <collision>
      <origin
        xyz="0 0 0"
        rpy="0 0 0" />
      <geometry>
        <mesh
          filename="meshes/right/right_finger4_link2.STL" />
      </geometry>
    </collision>
  </link>
  <joint
    name="right_finger4_joint2"
    type="fixed">
    <origin
      xyz="0.0022 0 0.004"
      rpy="0 0 0" />
    <parent
      link="right_finger4_link1" />
    <child
      link="right_finger4_link2" />
    <axis
      xyz="-1 0 0" />
    <limit
      lower="-0.37"
      upper="0.37"
      effort="0.1832"
      velocity="8.115781022" />
  </joint>
  <link
    name="right_finger4_link3">
    <inertial><origin xyz="-0.0011214 4.3494e-06 0.015763" rpy="0 0 0"/><mass value="0.0165"/><inertia ixx="1.47e-06" ixy="0.0" ixz="3e-08" iyy="1.44e-06" iyz="0.0" izz="4.5e-07"/></inertial>
    <visual>
      <origin
        xyz="0 0 0"
        rpy="0 0 0" />
      <geometry>
        <mesh
          filename="meshes/right/right_finger4_link3.STL" />
      </geometry>
      <material
        name="">
        <color
          rgba="0.89804 0.91765 0.92941 1" />
      </material>
    </visual>
    <collision>
      <origin
        xyz="0 0 0"
        rpy="0 0 0" />
      <geometry>
        <mesh
          filename="meshes/right/right_finger4_link3.STL" />
      </geometry>
    </collision>
  </link>
  <joint
    name="right_finger4_joint3"
    type="fixed">
    <origin
      xyz="-0.00475 0 0.043618"
      rpy="0 0 -0.00026861" />
    <parent
      link="right_finger4_link2" />
    <child
      link="right_finger4_link3" />
    <axis
      xyz="-0 1 -0" />
    <limit
      lower="-0.4765"
      upper="1.5487"
      effort="0.2249"
      velocity="12.86307659" />
  </joint>
  <link
    name="right_finger4_link4">
    <inertial><origin xyz="-0.00089436 1.7058e-05 0.0053518" rpy="0 0 0"/><mass value="0.014"/><inertia ixx="9.5e-07" ixy="0.0" ixz="1.4e-07" iyy="8.6e-07" iyz="-1e-08" izz="3e-07"/></inertial>
    <visual>
      <origin
        xyz="0 0 0"
        rpy="0 0 0" />
      <geometry>
        <mesh
          filename="meshes/right/right_finger4_link4.STL" />
      </geometry>
      <material
        name="">
        <color
          rgba="0.89804 0.91765 0.92941 1" />
      </material>
    </visual>
    <collision>
      <origin
        xyz="0 0 0"
        rpy="0 0 0" />
      <geometry>
        <mesh
          filename="meshes/right/right_finger4_link4.STL" />
      </geometry>
    </collision>
  </link>
  <joint
    name="right_finger4_joint4"
    type="fixed">
    <origin
      xyz="0 0 0.0295"
      rpy="0 0 0" />
    <parent
      link="right_finger4_link3" />
    <child
      link="right_finger4_link4" />
    <axis
      xyz="-0 1 -0" />
    <limit
      lower="-0.4777"
      upper="1.5634"
      effort="0.2044"
      velocity="13.57866158" />
  </joint>
  <link
    name="right_finger4_tip_link">
    <inertial><origin xyz="-0.00020322 1.528e-06 -0.0086106" rpy="0 0 0"/><mass value="0.00318"/><inertia ixx="2e-07" ixy="0.0" ixz="0.0" iyy="2.1e-07" iyz="0.0" izz="1.3e-07"/></inertial>
    <visual>
      <origin
        xyz="0 0 0"
        rpy="0 0 0" />
      <geometry>
        <mesh
          filename="meshes/right/right_finger4_tip_link.STL" />
      </geometry>
      <material
        name="">
        <color
          rgba="0.89804 0.91765 0.92941 1" />
      </material>
    </visual>
    <collision>
      <origin
        xyz="0 0 0"
        rpy="0 0 0" />
      <geometry>
        <mesh
          filename="meshes/right/right_finger4_tip_link.STL" />
      </geometry>
    </collision>
  </link>
  <joint
    name="right_finger4_tip_fixed"
    type="fixed">
    <origin
      xyz="-0.0010528 0 0.0267"
      rpy="0 0 0" />
    <parent
      link="right_finger4_link4" />
    <child
      link="right_finger4_tip_link" />
    <axis
      xyz="0 0 0" />
  </joint>
  <link
    name="right_finger5_link1">
    <inertial><origin xyz="-0.0013291 1.7235e-08 0.00031997" rpy="0 0 0"/><mass value="0.0032"/><inertia ixx="8e-08" ixy="0.0" ixz="-3e-08" iyy="7e-08" iyz="0.0" izz="8e-08"/></inertial>
    <visual>
      <origin
        xyz="0 0 0"
        rpy="0 0 0" />
      <geometry>
        <mesh
          filename="meshes/right/right_finger5_link1.STL" />
      </geometry>
      <material
        name="">
        <color
          rgba="0.89804 0.91765 0.92941 1" />
      </material>
    </visual>
    <!-- <collision>
      <origin
        xyz="0 0 0"
        rpy="0 0 0" />
      <geometry>
        <mesh
          filename="meshes/right/right_finger5_link1.STL" />
      </geometry>
    </collision> -->
  </link>
  <joint
    name="right_finger5_joint1"
    type="fixed">
    <origin
      xyz="-0.0022687 -0.034001 0.074281"
      rpy="0.19248 -0.092517 0.15767" />
    <parent
      link="right_palm_link" />
    <child
      link="right_finger5_link1" />
    <axis
      xyz="0 1 0" />
    <limit
      lower="-0.1626"
      upper="1.5585"
      effort="0.6441"
      velocity="8.203047484" />
  </joint>
  <link
    name="right_finger5_link2">
    <inertial><origin xyz="-0.0061576 -4.1475e-07 0.020911" rpy="0 0 0"/><mass value="0.033"/><inertia ixx="6.31e-06" ixy="0.0" ixz="-1.6e-07" iyy="6.34e-06" iyz="0.0" izz="8.9e-07"/></inertial>
    <visual>
      <origin
        xyz="0 0 0"
        rpy="0 0 0" />
      <geometry>
        <mesh
          filename="meshes/right/right_finger5_link2.STL" />
      </geometry>
      <material
        name="">
        <color
          rgba="0.89804 0.91765 0.92941 1" />
      </material>
    </visual>
    <collision>
      <origin
        xyz="0 0 0"
        rpy="0 0 0" />
      <geometry>
        <mesh
          filename="meshes/right/right_finger5_link2.STL" />
      </geometry>
    </collision>
  </link>
  <joint
    name="right_finger5_joint2"
    type="fixed">
    <origin
      xyz="0.0022 0 0.004"
      rpy="0 0 0" />
    <parent
      link="right_finger5_link1" />
    <child
      link="right_finger5_link2" />
    <axis
      xyz="-1 0 0" />
    <limit
      lower="-0.37"
      upper="0.37"
      effort="0.1798"
      velocity="8.115781022" />
  </joint>
  <link
    name="right_finger5_link3">
    <inertial><origin xyz="-0.0011214 4.3703e-06 0.015763" rpy="0 0 0"/><mass value="0.0165"/><inertia ixx="1.47e-06" ixy="0.0" ixz="3e-08" iyy="1.44e-06" iyz="0.0" izz="4.5e-07"/></inertial>
    <visual>
      <origin
        xyz="0 0 0"
        rpy="0 0 0" />
      <geometry>
        <mesh
          filename="meshes/right/right_finger5_link3.STL" />
      </geometry>
      <material
        name="">
        <color
          rgba="0.89804 0.91765 0.92941 1" />
      </material>
    </visual>
    <collision>
      <origin
        xyz="0 0 0"
        rpy="0 0 0" />
      <geometry>
        <mesh
          filename="meshes/right/right_finger5_link3.STL" />
      </geometry>
    </collision>
  </link>
  <joint
    name="right_finger5_joint3"
    type="fixed">
    <origin
      xyz="-0.00475 0 0.043618"
      rpy="0 0 -0.00026861" />
    <parent
      link="right_finger5_link2" />
    <child
      link="right_finger5_link3" />
    <axis
      xyz="-0 1 -0" />
    <limit
      lower="-0.4768"
      upper="1.5490"
      effort="0.2384"
      velocity="12.86307659" />
  </joint>
  <link
    name="right_finger5_link4">
    <inertial><origin xyz="-0.00089437 1.7063e-05 0.0053518" rpy="0 0 0"/><mass value="0.014"/><inertia ixx="9.5e-07" ixy="0.0" ixz="1.4e-07" iyy="8.6e-07" iyz="-1e-08" izz="3e-07"/></inertial>
    <visual>
      <origin
        xyz="0 0 0"
        rpy="0 0 0" />
      <geometry>
        <mesh
          filename="meshes/right/right_finger5_link4.STL" />
      </geometry>
      <material
        name="">
        <color
          rgba="0.89804 0.91765 0.92941 1" />
      </material>
    </visual>
    <collision>
      <origin
        xyz="0 0 0"
        rpy="0 0 0" />
      <geometry>
        <mesh
          filename="meshes/right/right_finger5_link4.STL" />
      </geometry>
    </collision>
  </link>
  <joint
    name="right_finger5_joint4"
    type="fixed">
    <origin
      xyz="0 0 0.0295"
      rpy="0 0 0" />
    <parent
      link="right_finger5_link3" />
    <child
      link="right_finger5_link4" />
    <axis
      xyz="-0 1 -0" />
    <limit
      lower="-0.4683"
      upper="1.5735"
      effort="0.1866"
      velocity="13.57866158" />
  </joint>
  <link
    name="right_finger5_tip_link">
    <inertial><origin xyz="-0.00020332 1.4872e-06 -0.0086111" rpy="0 0 0"/><mass value="0.00318"/><inertia ixx="2e-07" ixy="0.0" ixz="0.0" iyy="2.1e-07" iyz="0.0" izz="1.3e-07"/></inertial>
    <visual>
      <origin
        xyz="0 0 0"
        rpy="0 0 0" />
      <geometry>
        <mesh
          filename="meshes/right/right_finger5_tip_link.STL" />
      </geometry>
      <material
        name="">
        <color
          rgba="0.89804 0.91765 0.92941 1" />
      </material>
    </visual>
    <collision>
      <origin
        xyz="0 0 0"
        rpy="0 0 0" />
      <geometry>
        <mesh
          filename="meshes/right/right_finger5_tip_link.STL" />
      </geometry>
    </collision>
  </link>
  <joint
    name="right_finger5_tip_fixed"
    type="fixed">
    <origin
      xyz="-0.0010446 1.1308E-05 0.0267"
      rpy="0 0 0" />
    <parent
      link="right_finger5_link4" />
    <child
      link="right_finger5_tip_link" />
    <axis
      xyz="0 0 0" />
  </joint>
  <link name="LL_FOOT">
    <inertial>
      <origin xyz="0 0 0" rpy="0 0 0"/>
      <mass value="1e-9"/>
      <inertia ixx="0" ixy="0" ixz="0" iyy="0" iyz="0" izz="0"/>
    </inertial>
  </link>
  <joint name="LL_FOOT_frame" type="fixed">
    <origin xyz="0.04 0 -0.037" rpy="0 0 0"/>
    <parent link="left_ankle_roll_link"/>
    <child link="LL_FOOT"/>
  </joint>
  <link name="LR_FOOT">
    <inertial>
      <origin xyz="0 0 0" rpy="0 0 0"/>
      <mass value="1e-9"/>
      <inertia ixx="0" ixy="0" ixz="0" iyy="0" iyz="0" izz="0"/>
    </inertial>
  </link>
  <joint name="LR_FOOT_frame" type="fixed">
    <origin xyz="0.04 0 -0.037" rpy="0 0 0"/>
    <parent link="right_ankle_roll_link"/>
    <child link="LR_FOOT"/>
  </joint>
</robot>
